Workbook

Sheet 参数
A1: 参数（可改）
A2: 美元兑人民币汇率 (USD→CNY) | B2: 6.683751 | C2: ← 主表「汇率」列全部引用此格
A3: 更新日期/来源时间 | B3: Tue, 27 Oct 2026 00:02:31 +0000
A4: 数据来源 | B4: https://open.er-api.com/v6/latest/USD
A5: 说明 | B5: 每日运行「更新汇率.py」自动刷新；也可手动改 B2。
A7: 汇率请运行 更新汇率.py，或手动改 B2（勿用 WEBSERVICE）
A9: 固定费率默认
A10: 佣金率 | B10: 0.15 | C10: 主表 I–L 已按此写入，可按行单独改
A11: 退款率 | B11: 0.07
A12: 广告率 | B12: 0.15
A13: 提现费率 | B13: 0.01
A15: 地毯采购单价(RMB/㎡) | B15: 19 | C15: 主表 U 列已固定为19；改这里后请同步改主表U列，或改主表U为 =参数!$B$15
A16: 目标利润率(利润售价) | B16: 0.3 | C16: 利润售价按此利润率反推（含退税口径）
A17: 保本口径 | B17: 利润(售价+退税-总成本)≥0，售价ROUNDUP到分
A18: 必填项 | B18: 尺寸(C) + 起运地(BE) + FBA仓(BF)；渠道(BH)可空=自动最低价；竞品售价不用填
A19: 费用口径 | B19: 全部按「一件」：头程=单箱运费÷装数；FBA按单件净重；采购按单件面积×19
A20: 装数来源 | B20: 箱规「装箱数（件）」
A21: FBA规则 | B21: 美站2025非旺季家居口径，详见「FBA规则」表；可改该表费率参数
A22: 预计发货/出库日期 | B22: 46322 | C22: ← 改这个日期，FBA自动切换旺季/非旺季费率
A23: 当前季节 | B23: =IF(B22="","",IF(OR(AND(MONTH(B22)=10,DAY(B22)>=15),MONTH(B22)=11,MONTH(B22)=12,AND(MONTH(B22)=1,DAY(B22)<=14)),"旺季","非旺季")) | C23: 旺季：每年10/15–次年1/14（美站FBA假日旺季）
A24: 旺季开始(月-日) | B24: 10-15
A25: 旺季结束(月-日) | B25: 01-14
A26: 说明 | B26: 费用按「货件离开运营中心」日期计；填预计出库日即可估算

Sheet FBA规则
A1: Amazon美国站 FBA 配送费规则（非服装鞋靴·按发货日判旺季/非旺季）
A2: 主表发货日期在「参数!B22」。旺季=每年10/15–1/14。计费重→尺寸段→按季节查费率。
A4: 换算与计费重
A5: cm→inch | B5: 2.54
A6: kg→lb | B6: 2.2046226
A7: 抛重除数(inch³/lb) | B7: 139
A8: 计费重 | B8: MAX(实重lb, 抛重lb)；小标准件费用只用实重
A9: 围长相关 | B9: 长+围长 = 最长边 + 2×(中边+短边)
A11: 尺寸分段判定（同时满足才落入该段；从上到下先匹配小标准→大标准→大件→超大）
A12: 分段 | B12: 计费重上限(lb) | C12: 最长边(in) | D12: 中边(in) | E12: 最短边(in) | F12: 长+围长(in) | G12: 说明
A13: 小标准 Small Standard | B13: 1 | C13: 15 | D13: 12 | E13: 0.75 | G13: ≤16oz；费用按实重oz
A14: 大标准 Large Standard | B14: 20 | C14: 18 | D14: 14 | E14: 8 | G14: 最常见；计费重=max(实重,抛重)
A15: 大件 Large Bulky | B15: 50 | C15: 59 | D15: 33 | E15: 33 | F15: 130 | G15: 超标准尺寸但仍在大件限内
A16: 超大XL 0-50lb | B16: 50 | G16: 超出大件任一边/围长/或计费重逻辑
A17: 超大XL 50-70lb | B17: 70 | G17: 计费重>50且≤70
A18: 超大XL 70-150lb | B18: 150 | G18: 计费重>70且≤150
A19: 超大XL 150lb+ | G19: 计费重>150
A22: 配送费（USD/件，非旺季）
A23: 分段 | B23: 计费重条件 | C23: 费用公式 | D23: 备注
A24: 小标准 | B24: ≤16 oz 分档 | C24: 见右侧小标准表 / 或简化≈3.06~3.65 | D24: 地毯一般不会落入
A25: 大标准 | B25: ≤3 lb 分档；>3 lb | C25: ≤3lb查表；>3lb：6.92+0.08×每4oz(向上) | D25: 家居常见
A26: 大件 Large Bulky | B26: 任意 | C26: 9.61+0.38×(计费重lb-1)（按lb向上取整间隔） | D26: 超尺寸常用
A27: 超大 0-50 | B27: ≤50 | C27: 26.33+0.38×(计费重-1)
A28: 超大 50-70 | B28: 50+~70 | C28: 40.12+0.75×(计费重-51)
A29: 超大 70-150 | B29: 70+~150 | C29: 54.81+0.75×(计费重-71)
A30: 超大 150+ | B30: >150 | C30: 194.95+0.19×(计费重-151)
A33: 大标准费用档（计费重lb上限 → 非旺季 / 旺季）
A34: 上限lb | B34: 非旺季USD | C34: 旺季USD
A35: 0.25 | B35: 3.68 | C35: 3.92
A36: 0.5 | B36: 3.9 | C36: 4.16
A37: 0.75 | B37: 4.15 | C37: 4.43
A38: 1 | B38: 4.55 | C38: 4.84
A39: 1.25 | B39: 4.99 | C39: 5.29
A40: 1.5 | B40: 5.37 | C40: 5.68
A41: 1.75 | B41: 5.52 | C41: 5.84
A42: 2 | B42: 5.77 | C42: 6.1
A43: 2.25 | B43: 5.87 | C43: 6.24
A44: 2.5 | B44: 6.05 | C44: 6.44
A45: 2.75 | B45: 6.21 | C45: 6.61
A46: 3 | B46: 6.62 | C46: 7.03
...

Sheet 采购成本对比
B1: ①产品信息（箱规带出·装数用于把整箱费用摊到一件） | F1: 不用填 | G1: ②自动售价（按「一件」核算） | I1: ③固定费率/汇率 | N1: ④单件尺寸/计费重/季节FBA（箱规尺寸→计费重→分段；费用随参数!发货日旺季切换） | U1: ⑤采购（一件·平米×19） | Y1: ⑥保本明细（一件·对应保本售价） | AN1: ⑦利润明细（一件·对应利润售价） | BE1: ⑧头程物流（先算整箱运费，再÷装数摊到一件） | BM1: 说明 | CF1: FBA季节 | CG1: 发货日
B2: 款式 | C2: 尺寸 | D2: 装数(件/箱) | E2: 图片 | F2: 竞品售价 | G2: 保本售价 | H2: 利润售价 | I2: 佣金率 | J2: 退款率 | K2: 广告率 | L2: 提现费率 | M2: 汇率 | N2: 单件净重(kg) | O2: 单件长(cm) | P2: 单件宽(cm) | Q2: 单件高(cm) | R2: FBA计费重(lb) | S2: FBA尺寸分段 | T2: 长+围长(in) | U2: 单价(RMB/㎡) | V2: 采购(RMB) | W2: 重量(计价备用) | X2: 采购价(USD) | Y2: 采购/售价比值(保本) | Z2: 中转调拨费 | AA2: 头程运费(RMB/件) | AB2: FBA配送费(USD/件) | AC2: 佣金(USD) | AD2: 退款(USD) | AE2: 广告(USD) | AF2: 提现(USD) | AG2: 仓储费率 | AH2: 仓储费(USD) | AI2: 优惠券(USD) | AJ2: 总成本(保本) | AK2: 退税 | AL2: 单品利润(保本) | AM2: 利润率(保本) | AN2: 采购/售价比值(销售) | AO2: 中转调拨费 | AP2: 头程运费(RMB/件) | AQ2: FBA配送费(USD/件) | AR2: 佣金(USD) | AS2: 退款(USD) | AT2: 广告(USD) | AU2: 提现(USD) | AV2: 仓储费率 | AW2: 仓储费(USD) | AX2: 优惠券(USD) | AY2: 总成本(销售) | AZ2: 退税 | BA2: 利润(销售-退税) | BB2: 利润率(销售-退税) | BC2: 利润(销售) | BD2: 利润率(销售) | BE2: 起运地 | BF2: FBA仓 | BG2: 运输方式 | BH2: 海运渠道(可选) | BI2: 海运单价(RMB/KG) | BJ2: 单箱计费重(kg) | BK2: 单箱海运费(RMB) | BL2: 陆运运费(RMB/箱) | BM2: 计价说明 | BO2: 可选渠道1 | BP2: 可选渠道2 | BQ2: 可选渠道3 | BR2: 可选渠道4 | BS2: 可选渠道5 | BT2: 可选渠道6 | BU2: 可选渠道7 | BV2: 可选渠道8 | BW2: 可选渠道9 | BX2: 可选渠道10 | BY2: 可选渠道11 | BZ2: 可选渠道12 | CA2: 可选渠道13 | CB2: 可选渠道14 | CC2: 可选渠道15 | CD2: 固定成本USD(内部) | CE2: 变动费率合计(内部) | CF2: =参数!B23 | CG2: =参数!B22
A3: 已列出箱规全部可算尺寸共22行（起运义乌/仓ABE8/渠道最低价；发货2026-10-27=旺季）。详见工作表「全尺寸利润」汇总。改仓或发货日后主表公式会变，汇总表需重算。
A4: 数据行 | C4: 2'3' | D4: =IF(C4="","",VLOOKUP($C4,箱规!$A$2:$S$23,9,FALSE)) | G4: =IF(OR(CD4="",CE4="",CE4>=1,X4=""),"",ROUNDUP((CD4-0.13*X4/1.13)/(1-CE4),2)) | H4: =IF(OR(CD4="",CE4="",X4=""),"",IF((1-CE4-参数!$B$16)<=0,"费率过高",ROUND((CD4-0.13*X4/1.13)/(1-CE4-参数!$B$16),2))) | I4: 0.15 | J4: 0.07 | K4: 0.15 | L4: 0.01 | M4: =参数!$B$2 | N4: =IF(C4="","",VLOOKUP($C4,箱规!$A$2:$S$23,14,FALSE)) | O4: =IF(C4="","",VLOOKUP($C4,箱规!$A$2:$S$23,5,FALSE)) | P4: =IF(C4="","",VLOOKUP($C4,箱规!$A$2:$S$23,6,FALSE)) | Q4: =IF(C4="","",VLOOKUP($C4,箱规!$A$2:$S$23,7,FALSE)) | R4: =IF(OR(N4="",O4="",P4="",Q4=""),"",MAX(N4*FBA规则!$B$6,(O4/FBA规则!$B$5)*(P4/FBA规则!$B$5)*(Q4/FBA规则!$B$5)/FBA规则!$B$7)) | S4: =IF(R4="","",IF(AND(N4*FBA规则!$B$6<=1,MAX(O4,P4,Q4)/FBA规则!$B$5<=15,MEDIAN(O4,P4,Q4)/FBA规则!$B$5<=12,MIN(O4,P4,Q4)/FBA规则!$B$5<=0.75),"小标准",IF(AND(R4<=20,MAX(O4,P4,Q4)/FBA规则!$B$5<=18,MEDIAN(O4,P4,Q4)/FBA规则!$B$5<=14,MIN(O4,P4,Q4)/FBA规则!$B$5<=8),"大标准",IF(AND(R4<=50,MAX(O4,P4,Q4)/FBA规则!$B$5<=59,MEDIAN(O4,P4,Q4)/FBA规则!$B$5<=33,MIN(O4,P4,Q4)/FBA规则!$B$5<=33,T4<=130),"大件",IF(R4<=50,"超大0-50lb",IF(R4<=70,"超大50-70lb",IF(R4<=150,"超大70-150lb","超大150lb+"))))))) | T4: =IF(OR(O4="",P4="",Q4=""),"",MAX(O4,P4,Q4)/FBA规则!$B$5+2*((MEDIAN(O4,P4,Q4)+MIN(O4,P4,Q4))/FBA规则!$B$5)) | U4: =参数!$B$15 | V4: =IF(OR(C4="",U4=""),"",(IF(OR(VLOOKUP($C4,箱规!$A$2:$S$23,4,FALSE)="",VLOOKUP($C4,箱规!$A$2:$S$23,4,FALSE)=0),VLOOKUP($C4,箱规!$A$2:$S$23,2,FALSE)*VLOOKUP($C4,箱规!$A$2:$S$23,3,FALSE)/10000,VLOOKUP($C4,箱规!$A$2:$S$23,4,FALSE)))*U4) | X4: =IF(AND(V4<>"",M4<>""),V4/M4,IF(AND(W4<>"",M4<>""),W4*1.13/M4,"")) | Y4: =IF(OR(X4="",G4=""),"",X4/G4) | AA4: =IF(OR(D4="",D4=0),"",IF(BG4="陆运",IF(BL4="",0,BL4)/D4,IF(BG4="海运",IF(BK4="",0,BK4)/D4,IF(BG4="海运+陆运",(IF(BK4="",0,BK4)+IF(BL4="",0,BL4))/D4,IF(BK4="",0,BK4)/D4)))) | AB4: =IF(OR(S4="",R4="",参数!$B$23=""),"",IF(S4="小标准",IFERROR(INDEX(FBA规则!$B$58:$C$65,MATCH(N4*FBA规则!$B$6*16,FBA规则!$A$58:$A$65,1),IF(参数!$B$23="旺季",2,1)),INDEX(FBA规则!$B$65:$C$65,1,IF(参数!$B$23="旺季",2,1))),IF(S4="大标准",IF(R4<=3,IFERROR(INDEX(FBA规则!$B$35:$C$46,MATCH(R4,FBA规则!$A$35:$A$46,1),IF(参数!$B$23="旺季",2,1)),INDEX(FBA规则!$B$46:$C$46,1,IF(参数!$B$23="旺季",2,1))),INDEX(FBA规则!$B$47:$C$47,1,IF(参数!$B$23="旺季",2,1))+FBA规则!$D$47*CEILING((R4-3)*4,1)),IF(S4="大件",INDEX(FBA规则!$B$50:$C$50,1,IF(参数!$B$23="旺季",2,1))+FBA规则!$D$50*MAX(0,CEILING(R4,1)-1),IF(S4="超大0-50lb",INDEX(FBA规则!$B$51:$C$51,1,IF(参数!$B$23="旺季",2,1))+FBA规则!$D$51*MAX(0,CEILING(R4,1)-1),IF(S4="超大50-70lb",INDEX(FBA规则!$B$52:$C$52,1,IF(参数!$B$23="旺季",2,1))+FBA规则!$D$52*MAX(0,R4-FBA规则!$F$52),IF(S4="超大70-150lb",INDEX(FBA规则!$B$53:$C$53,1,IF(参数!$B$23="旺季",2,1))+FBA规则!$D$53*MAX(0,R4-FBA规则!$F$53),INDEX(FBA规则!$B$54:$C$54,1,IF(参数!$B$23="旺季",2,1))+FBA规则!$D$54*MAX(0,R4-FBA规则!$F$54)))))))) | AC4: =IF(OR(G4="",I4=""),"",G4*I4) | AD4: =IF(OR(G4="",J4=""),"",G4*J4) | AE4: =IF(OR(G4="",K4=""),"",G4*K4) | AF4: =IF(OR(G4="",L4=""),"",G4*L4) | AG4: 0.02 | AH4: =IF(OR(G4="",AG4=""),"",G4*AG4) | AJ4: =IF(X4="","",X4+IF(OR(AA4="",M4=""),0,AA4/M4)+SUM(AB4:AF4)+IF(AH4="",0,AH4)+IF(AI4="",0,AI4)) | AK4: =IF(X4="","",0.13*X4/1.13) | AL4: =IF(OR(G4="",AJ4=""),"",G4+AK4-AJ4) | AM4: =IF(OR(AL4="",G4=""),"",AL4/G4) | AN4: =IF(OR(X4="",H4=""),"",X4/H4) | AP4: =AA4 | AQ4: =IF(OR(S4="",R4="",参数!$B$23=""),"",IF(S4="小标准",IFERROR(INDEX(FBA规则!$B$58:$C$65,MATCH(N4*FBA规则!$B$6*16,FBA规则!$A$58:$A$65,1),IF(参数!$B$23="旺季",2,1)),INDEX(FBA规则!$B$65:$C$65,1,IF(参数!$B$23="旺季",2,1))),IF(S4="大标准",IF(R4<=3,IFERROR(INDEX(FBA规则!$B$35:$C$46,MATCH(R4,FBA规则!$A$35:$A$46,1),IF(参数!$B$23="旺季",2,1)),INDEX(FBA规则!$B$46:$C$46,1,IF(参数!$B$23="旺季",2,1))),INDEX(FBA规则!$B$47:$C$47,1,IF(参数!$B$23="旺季",2,1))+FBA规则!$D$47*CEILING((R4-3)*4,1)),IF(S4="大件",INDEX(FBA规则!$B$50:$C$50,1,IF(参数!$B$23="旺季",2,1))+FBA规则!$D$50*MAX(0,CEILING(R4,1)-1),IF(S4="超大0-50lb",INDEX(FBA规则!$B$51:$C$51,1,IF(参数!$B$23="旺季",2,1))+FBA规则!$D$51*MAX(0,CEILING(R4,1)-1),IF(S4="超大50-70lb",INDEX(FBA规则!$B$52:$C$52,1,IF(参数!$B$23="旺季",2,1))+FBA规则!$D$52*MAX(0,R4-FBA规则!$F$52),IF(S4="超大70-150lb",INDEX(FBA规则!$B$53:$C$53,1,IF(参数!$B$23="旺季",2,1))+FBA规则!$D$53*MAX(0,R4-FBA规则!$F$53),INDEX(FBA规则!$B$54:$C$54,1,IF(参数!$B$23="旺季",2,1))+FBA规则!$D$54*MAX(0,R4-FBA规则!$F$54)))))))) | AR4: =IF(OR(H4="",I4=""),"",H4*I4) | AS4: =IF(OR(H4="",J4=""),"",H4*J4) | AT4: =IF(OR(H4="",K4=""),"",H4*K4) | AU4: =IF(OR(H4="",L4=""),"",H4*L4) | AV4: 0.02 | AW4: =IF(OR(H4="",AV4=""),"",H4*AV4) | AY4: =IF(X4="","",X4+IF(OR(AP4="",M4=""),0,AP4/M4)+SUM(AQ4:AU4)+IF(AW4="",0,AW4)+IF(AX4="",0,AX4)) | AZ4: =IF(X4="","",0.13*X4/1.13) | BA4: =IF(OR(H4="",AY4=""),"",H4+AZ4-AY4) | BB4: =IF(OR(BA4="",H4=""),"",BA4/H4) | BC4: =IF(OR(H4="",AY4=""),"",H4-AY4) | BD4: =IF(OR(BC4="",H4=""),"",BC4/H4) | BE4: 义乌 | BF4: ABE8 | BG4: 海运 | BH4: （最低价） | BI4: =IF(OR(BE4="",BF4=""),"",IF(AND(BH4<>"",BH4<>"（最低价）"),IFERROR(IF(SUMIFS(海运报价!$F$2:$F$2000,海运报价!$C$2:$C$2000,BH4,海运报价!$D$2:$D$2000,BE4,海运报价!$E$2:$E$2000,BF4)=0,"",SUMIFS(海运报价!$F$2:$F$2000,海运报价!$C$2:$C$2000,BH4,海运报价!$D$2:$D$2000,BE4,海运报价!$E$2:$E$2000,BF4)),""),IFERROR(IF(SUMIFS(海运下拉!$H$2:$H$311,海运下拉!$F$2:$F$311,BE4,海运下拉!$G$2:$G$311,BF4)=0,"",SUMIFS(海运下拉!$H$2:$H$311,海运下拉!$F$2:$F$311,BE4,海运下拉!$G$2:$G$311,BF4)),""))) | BJ4: =IF(C4="","",VLOOKUP($C4,箱规!$A$2:$S$23,18,FALSE)) | BK4: =IF(OR(BI4="",BJ4=""),"",BJ4*(BI4+IF(AND(BH4<>"",BH4<>"（最低价）"),IFERROR(AVERAGEIFS(海运报价!$H$2:$H$2000,海运报价!$C$2:$C$2000,BH4,海运报价!$D$2:$D$2000,BE4,海运报价!$E$2:$E$2000,BF4),0),IFERROR(SUMIFS(海运下拉!$J$2:$J$311,海运下拉!$F$2:$F$311,BE4,海运下拉!$G$2:$G$311,BF4),0)))) | BM4: =IF(OR(BE4="",BF4=""),"请选起运地+FBA仓",IF(AND(AND(BH4<>"",BH4<>"（最低价）"),BI4=""),"⚠该渠道不服务此仓：请重选渠道，或选「（最低价）」",IF(BI4="","无报价：请换起运地/仓库",IF(AND(BH4<>"",BH4<>"（最低价）"),"按你选的渠道「"&BH4&"」计价","按最低价「"&IFERROR(SUMIFS(海运下拉!$I$2:$I$311,海运下拉!$F$2:$F$311,BE4,海运下拉!$G$2:$G$311,BF4),"")&"」（渠道默认最低价）")))) | BO4: =IF(OR($BE4="",$BF4=""),"",IFERROR(INDEX(海运报价!$C$2:$C$2000,AGGREGATE(15,6,(ROW(海运报价!$C$2:$C$2000)-ROW(海运报价!$C$2)+1)/((海运报价!$D$2:$D$2000=$BE4)*(海运报价!$E$2:$E$2000=$BF4)),1)),"")) | BP4: =IF(OR($BE4="",$BF4=""),"",IFERROR(INDEX(海运报价!$C$2:$C$2000,AGGREGATE(15,6,(ROW(海运报价!$C$2:$C$2000)-ROW(海运报价!$C$2)+1)/((海运报价!$D$2:$D$2000=$BE4)*(海运报价!$E$2:$E$2000=$BF4)),2)),"")) | BQ4: =IF(OR($BE4="",$BF4=""),"",IFERROR(INDEX(海运报价!$C$2:$C$2000,AGGREGATE(15,6,(ROW(海运报价!$C$2:$C$2000)-ROW(海运报价!$C$2)+1)/((海运报价!$D$2:$D$2000=$BE4)*(海运报价!$E$2:$E$2000=$BF4)),3)),"")) | BR4: =IF(OR($BE4="",$BF4=""),"",IFERROR(INDEX(海运报价!$C$2:$C$2000,AGGREGATE(15,6,(ROW(海运报价!$C$2:$C$2000)-ROW(海运报价!$C$2)+1)/((海运报价!$D$2:$D$2000=$BE4)*(海运报价!$E$2:$E$2000=$BF4)),4)),"")) | BS4: =IF(OR($BE4="",$BF4=""),"",IFERROR(INDEX(海运报价!$C$2:$C$2000,AGGREGATE(15,6,(ROW(海运报价!$C$2:$C$2000)-ROW(海运报价!$C$2)+1)/((海运报价!$D$2:$D$2000=$BE4)*(海运报价!$E$2:$E$2000=$BF4)),5)),"")) | BT4: =IF(OR($BE4="",$BF4=""),"",IFERROR(INDEX(海运报价!$C$2:$C$2000,AGGREGATE(15,6,(ROW(海运报价!$C$2:$C$2000)-ROW(海运报价!$C$2)+1)/((海运报价!$D$2:$D$2000=$BE4)*(海运报价!$E$2:$E$2000=$BF4)),6)),"")) | BU4: =IF(OR($BE4="",$BF4=""),"",IFERROR(INDEX(海运报价!$C$2:$C$2000,AGGREGATE(15,6,(ROW(海运报价!$C$2:$C$2000)-ROW(海运报价!$C$2)+1)/((海运报价!$D$2:$D$2000=$BE4)*(海运报价!$E$2:$E$2000=$BF4)),7)),"")) | BV4: =IF(OR($BE4="",$BF4=""),"",IFERROR(INDEX(海运报价!$C$2:$C$2000,AGGREGATE(15,6,(ROW(海运报价!$C$2:$C$2000)-ROW(海运报价!$C$2)+1)/((海运报价!$D$2:$D$2000=$BE4)*(海运报价!$E$2:$E$2000=$BF4)),8)),"")) | BW4: =IF(OR($BE4="",$BF4=""),"",IFERROR(INDEX(海运报价!$C$2:$C$2000,AGGREGATE(15,6,(ROW(海运报价!$C$2:$C$2000)-ROW(海运报价!$C$2)+1)/((海运报价!$D$2:$D$2000=$BE4)*(海运报价!$E$2:$E$2000=$BF4)),9)),"")) | BX4: =IF(OR($BE4="",$BF4=""),"",IFERROR(INDEX(海运报价!$C$2:$C$2000,AGGREGATE(15,6,(ROW(海运报价!$C$2:$C$2000)-ROW(海运报价!$C$2)+1)/((海运报价!$D$2:$D$2000=$BE4)*(海运报价!$E$2:$E$2000=$BF4)),10)),"")) | BY4: =IF(OR($BE4="",$BF4=""),"",IFERROR(INDEX(海运报价!$C$2:$C$2000,AGGREGATE(15,6,(ROW(海运报价!$C$2:$C$2000)-ROW(海运报价!$C$2)+1)/((海运报价!$D$2:$D$2000=$BE4)*(海运报价!$E$2:$E$2000=$BF4)),11)),"")) | BZ4: =IF(OR($BE4="",$BF4=""),"",IFERROR(INDEX(海运报价!$C$2:$C$2000,AGGREGATE(15,6,(ROW(海运报价!$C$2:$C$2000)-ROW(海运报价!$C$2)+1)/((海运报价!$D$2:$D$2000=$BE4)*(海运报价!$E$2:$E$2000=$BF4)),12)),"")) | CA4: =IF(OR($BE4="",$BF4=""),"",IFERROR(INDEX(海运报价!$C$2:$C$2000,AGGREGATE(15,6,(ROW(海运报价!$C$2:$C$2000)-ROW(海运报价!$C$2)+1)/((海运报价!$D$2:$D$2000=$BE4)*(海运报价!$E$2:$E$2000=$BF4)),13)),"")) | CB4: =IF(OR($BE4="",$BF4=""),"",IFERROR(INDEX(海运报价!$C$2:$C$2000,AGGREGATE(15,6,(ROW(海运报价!$C$2:$C$2000)-ROW(海运报价!$C$2)+1)/((海运报价!$D$2:$D$2000=$BE4)*(海运报价!$E$2:$E$2000=$BF4)),14)),"")) | CC4: =IF(OR($BE4="",$BF4=""),"",IFERROR(INDEX(海运报价!$C$2:$C$2000,AGGREGATE(15,6,(ROW(海运报价!$C$2:$C$2000)-ROW(海运报价!$C$2)+1)/((海运报价!$D$2:$D$2000=$BE4)*(海运报价!$E$2:$E$2000=$BF4)),15)),"")) | CD4: =IF(OR(X4="",M4=""),"",X4+IF(OR(AA4="",M4=""),0,AA4/M4)+IF(AB4="",0,AB4)+IF(AI4="",0,AI4)+IF(Z4="",0,Z4)) | CE4: =I4+J4+K4+L4+AG4
C5: 2'5' | D5: =IF(C5="","",VLOOKUP($C5,箱规!$A$2:$S$23,9,FALSE)) | G5: =IF(OR(CD5="",CE5="",CE5>=1,X5=""),"",ROUNDUP((CD5-0.13*X5/1.13)/(1-CE5),2)) | H5: =IF(OR(CD5="",CE5="",X5=""),"",IF((1-CE5-参数!$B$16)<=0,"费率过高",ROUND((CD5-0.13*X5/1.13)/(1-CE5-参数!$B$16),2))) | I5: 0.15 | J5: 0.07 | K5: 0.15 | L5: 0.01 | M5: =参数!$B$2 | N5: =IF(C5="","",VLOOKUP($C5,箱规!$A$2:$S$23,14,FALSE)) | O5: =IF(C5="","",VLOOKUP($C5,箱规!$A$2:$S$23,5,FALSE)) | P5: =IF(C5="","",VLOOKUP($C5,箱规!$A$2:$S$23,6,FALSE)) | Q5: =IF(C5="","",VLOOKUP($C5,箱规!$A$2:$S$23,7,FALSE)) | R5: =IF(OR(N5="",O5="",P5="",Q5=""),"",MAX(N5*FBA规则!$B$6,(O5/FBA规则!$B$5)*(P5/FBA规则!$B$5)*(Q5/FBA规则!$B$5)/FBA规则!$B$7)) | S5: =IF(R5="","",IF(AND(N5*FBA规则!$B$6<=1,MAX(O5,P5,Q5)/FBA规则!$B$5<=15,MEDIAN(O5,P5,Q5)/FBA规则!$B$5<=12,MIN(O5,P5,Q5)/FBA规则!$B$5<=0.75),"小标准",IF(AND(R5<=20,MAX(O5,P5,Q5)/FBA规则!$B$5<=18,MEDIAN(O5,P5,Q5)/FBA规则!$B$5<=14,MIN(O5,P5,Q5)/FBA规则!$B$5<=8),"大标准",IF(AND(R5<=50,MAX(O5,P5,Q5)/FBA规则!$B$5<=59,MEDIAN(O5,P5,Q5)/FBA规则!$B$5<=33,MIN(O5,P5,Q5)/FBA规则!$B$5<=33,T5<=130),"大件",IF(R5<=50,"超大0-50lb",IF(R5<=70,"超大50-70lb",IF(R5<=150,"超大70-150lb","超大150lb+"))))))) | T5: =IF(OR(O5="",P5="",Q5=""),"",MAX(O5,P5,Q5)/FBA规则!$B$5+2*((MEDIAN(O5,P5,Q5)+MIN(O5,P5,Q5))/FBA规则!$B$5)) | U5: =参数!$B$15 | V5: =IF(OR(C5="",U5=""),"",(IF(OR(VLOOKUP($C5,箱规!$A$2:$S$23,4,FALSE)="",VLOOKUP($C5,箱规!$A$2:$S$23,4,FALSE)=0),VLOOKUP($C5,箱规!$A$2:$S$23,2,FALSE)*VLOOKUP($C5,箱规!$A$2:$S$23,3,FALSE)/10000,VLOOKUP($C5,箱规!$A$2:$S$23,4,FALSE)))*U5) | X5: =IF(AND(V5<>"",M5<>""),V5/M5,IF(AND(W5<>"",M5<>""),W5*1.13/M5,"")) | Y5: =IF(OR(X5="",G5=""),"",X5/G5) | AA5: =IF(OR(D5="",D5=0),"",IF(BG5="陆运",IF(BL5="",0,BL5)/D5,IF(BG5="海运",IF(BK5="",0,BK5)/D5,IF(BG5="海运+陆运",(IF(BK5="",0,BK5)+IF(BL5="",0,BL5))/D5,IF(BK5="",0,BK5)/D5)))) | AB5: =IF(OR(S5="",R5="",参数!$B$23=""),"",IF(S5="小标准",IFERROR(INDEX(FBA规则!$B$58:$C$65,MATCH(N5*FBA规则!$B$6*16,FBA规则!$A$58:$A$65,1),IF(参数!$B$23="旺季",2,1)),INDEX(FBA规则!$B$65:$C$65,1,IF(参数!$B$23="旺季",2,1))),IF(S5="大标准",IF(R5<=3,IFERROR(INDEX(FBA规则!$B$35:$C$46,MATCH(R5,FBA规则!$A$35:$A$46,1),IF(参数!$B$23="旺季",2,1)),INDEX(FBA规则!$B$46:$C$46,1,IF(参数!$B$23="旺季",2,1))),INDEX(FBA规则!$B$47:$C$47,1,IF(参数!$B$23="旺季",2,1))+FBA规则!$D$47*CEILING((R5-3)*4,1)),IF(S5="大件",INDEX(FBA规则!$B$50:$C$50,1,IF(参数!$B$23="旺季",2,1))+FBA规则!$D$50*MAX(0,CEILING(R5,1)-1),IF(S5="超大0-50lb",INDEX(FBA规则!$B$51:$C$51,1,IF(参数!$B$23="旺季",2,1))+FBA规则!$D$51*MAX(0,CEILING(R5,1)-1),IF(S5="超大50-70lb",INDEX(FBA规则!$B$52:$C$52,1,IF(参数!$B$23="旺季",2,1))+FBA规则!$D$52*MAX(0,R5-FBA规则!$F$52),IF(S5="超大70-150lb",INDEX(FBA规则!$B$53:$C$53,1,IF(参数!$B$23="旺季",2,1))+FBA规则!$D$53*MAX(0,R5-FBA规则!$F$53),INDEX(FBA规则!$B$54:$C$54,1,IF(参数!$B$23="旺季",2,1))+FBA规则!$D$54*MAX(0,R5-FBA规则!$F$54)))))))) | AC5: =IF(OR(G5="",I5=""),"",G5*I5) | AD5: =IF(OR(G5="",J5=""),"",G5*J5) | AE5: =IF(OR(G5="",K5=""),"",G5*K5) | AF5: =IF(OR(G5="",L5=""),"",G5*L5) | AG5: 0.02 | AH5: =IF(OR(G5="",AG5=""),"",G5*AG5) | AJ5: =IF(X5="","",X5+IF(OR(AA5="",M5=""),0,AA5/M5)+SUM(AB5:AF5)+IF(AH5="",0,AH5)+IF(AI5="",0,AI5)) | AK5: =IF(X5="","",0.13*X5/1.13) | AL5: =IF(OR(G5="",AJ5=""),"",G5+AK5-AJ5) | AM5: =IF(OR(AL5="",G5=""),"",AL5/G5) | AN5: =IF(OR(X5="",H5=""),"",X5/H5) | AP5: =AA5 | AQ5: =IF(OR(S5="",R5="",参数!$B$23=""),"",IF(S5="小标准",IFERROR(INDEX(FBA规则!$B$58:$C$65,MATCH(N5*FBA规则!$B$6*16,FBA规则!$A$58:$A$65,1),IF(参数!$B$23="旺季",2,1)),INDEX(FBA规则!$B$65:$C$65,1,IF(参数!$B$23="旺季",2,1))),IF(S5="大标准",IF(R5<=3,IFERROR(INDEX(FBA规则!$B$35:$C$46,MATCH(R5,FBA规则!$A$35:$A$46,1),IF(参数!$B$23="旺季",2,1)),INDEX(FBA规则!$B$46:$C$46,1,IF(参数!$B$23="旺季",2,1))),INDEX(FBA规则!$B$47:$C$47,1,IF(参数!$B$23="旺季",2,1))+FBA规则!$D$47*CEILING((R5-3)*4,1)),IF(S5="大件",INDEX(FBA规则!$B$50:$C$50,1,IF(参数!$B$23="旺季",2,1))+FBA规则!$D$50*MAX(0,CEILING(R5,1)-1),IF(S5="超大0-50lb",INDEX(FBA规则!$B$51:$C$51,1,IF(参数!$B$23="旺季",2,1))+FBA规则!$D$51*MAX(0,CEILING(R5,1)-1),IF(S5="超大50-70lb",INDEX(FBA规则!$B$52:$C$52,1,IF(参数!$B$23="旺季",2,1))+FBA规则!$D$52*MAX(0,R5-FBA规则!$F$52),IF(S5="超大70-150lb",INDEX(FBA规则!$B$53:$C$53,1,IF(参数!$B$23="旺季",2,1))+FBA规则!$D$53*MAX(0,R5-FBA规则!$F$53),INDEX(FBA规则!$B$54:$C$54,1,IF(参数!$B$23="旺季",2,1))+FBA规则!$D$54*MAX(0,R5-FBA规则!$F$54)))))))) | AR5: =IF(OR(H5="",I5=""),"",H5*I5) | AS5: =IF(OR(H5="",J5=""),"",H5*J5) | AT5: =IF(OR(H5="",K5=""),"",H5*K5) | AU5: =IF(OR(H5="",L5=""),"",H5*L5) | AV5: 0.02 | AW5: =IF(OR(H5="",AV5=""),"",H5*AV5) | AY5: =IF(X5="","",X5+IF(OR(AP5="",M5=""),0,AP5/M5)+SUM(AQ5:AU5)+IF(AW5="",0,AW5)+IF(AX5="",0,AX5)) | AZ5: =IF(X5="","",0.13*X5/1.13) | BA5: =IF(OR(H5="",AY5=""),"",H5+AZ5-AY5) | BB5: =IF(OR(BA5="",H5=""),"",BA5/H5) | BC5: =IF(OR(H5="",AY5=""),"",H5-AY5) | BD5: =IF(OR(BC5="",H5=""),"",BC5/H5) | BE5: 义乌 | BF5: ABE8 | BG5: 海运 | BH5: （最低价） | BI5: =IF(OR(BE5="",BF5=""),"",IF(AND(BH5<>"",BH5<>"（最低价）"),IFERROR(IF(SUMIFS(海运报价!$F$2:$F$2000,海运报价!$C$2:$C$2000,BH5,海运报价!$D$2:$D$2000,BE5,海运报价!$E$2:$E$2000,BF5)=0,"",SUMIFS(海运报价!$F$2:$F$2000,海运报价!$C$2:$C$2000,BH5,海运报价!$D$2:$D$2000,BE5,海运报价!$E$2:$E$2000,BF5)),""),IFERROR(IF(SUMIFS(海运下拉!$H$2:$H$311,海运下拉!$F$2:$F$311,BE5,海运下拉!$G$2:$G$311,BF5)=0,"",SUMIFS(海运下拉!$H$2:$H$311,海运下拉!$F$2:$F$311,BE5,海运下拉!$G$2:$G$311,BF5)),""))) | BJ5: =IF(C5="","",VLOOKUP($C5,箱规!$A$2:$S$23,18,FALSE)) | BK5: =IF(OR(BI5="",BJ5=""),"",BJ5*(BI5+IF(AND(BH5<>"",BH5<>"（最低价）"),IFERROR(AVERAGEIFS(海运报价!$H$2:$H$2000,海运报价!$C$2:$C$2000,BH5,海运报价!$D$2:$D$2000,BE5,海运报价!$E$2:$E$2000,BF5),0),IFERROR(SUMIFS(海运下拉!$J$2:$J$311,海运下拉!$F$2:$F$311,BE5,海运下拉!$G$2:$G$311,BF5),0)))) | BM5: =IF(OR(BE5="",BF5=""),"请选起运地+FBA仓",IF(AND(AND(BH5<>"",BH5<>"（最低价）"),BI5=""),"⚠该渠道不服务此仓：请重选渠道，或选「（最低价）」",IF(BI5="","无报价：请换起运地/仓库",IF(AND(BH5<>"",BH5<>"（最低价）"),"按你选的渠道「"&BH5&"」计价","按最低价「"&IFERROR(SUMIFS(海运下拉!$I$2:$I$311,海运下拉!$F$2:$F$311,BE5,海运下拉!$G$2:$G$311,BF5),"")&"」（渠道默认最低价）")))) | BO5: =IF(OR($BE5="",$BF5=""),"",IFERROR(INDEX(海运报价!$C$2:$C$2000,AGGREGATE(15,6,(ROW(海运报价!$C$2:$C$2000)-ROW(海运报价!$C$2)+1)/((海运报价!$D$2:$D$2000=$BE5)*(海运报价!$E$2:$E$2000=$BF5)),1)),"")) | BP5: =IF(OR($BE5="",$BF5=""),"",IFERROR(INDEX(海运报价!$C$2:$C$2000,AGGREGATE(15,6,(ROW(海运报价!$C$2:$C$2000)-ROW(海运报价!$C$2)+1)/((海运报价!$D$2:$D$2000=$BE5)*(海运报价!$E$2:$E$2000=$BF5)),2)),"")) | BQ5: =IF(OR($BE5="",$BF5=""),"",IFERROR(INDEX(海运报价!$C$2:$C$2000,AGGREGATE(15,6,(ROW(海运报价!$C$2:$C$2000)-ROW(海运报价!$C$2)+1)/((海运报价!$D$2:$D$2000=$BE5)*(海运报价!$E$2:$E$2000=$BF5)),3)),"")) | BR5: =IF(OR($BE5="",$BF5=""),"",IFERROR(INDEX(海运报价!$C$2:$C$2000,AGGREGATE(15,6,(ROW(海运报价!$C$2:$C$2000)-ROW(海运报价!$C$2)+1)/((海运报价!$D$2:$D$2000=$BE5)*(海运报价!$E$2:$E$2000=$BF5)),4)),"")) | BS5: =IF(OR($BE5="",$BF5=""),"",IFERROR(INDEX(海运报价!$C$2:$C$2000,AGGREGATE(15,6,(ROW(海运报价!$C$2:$C$2000)-ROW(海运报价!$C$2)+1)/((海运报价!$D$2:$D$2000=$BE5)*(海运报价!$E$2:$E$2000=$BF5)),5)),"")) | BT5: =IF(OR($BE5="",$BF5=""),"",IFERROR(INDEX(海运报价!$C$2:$C$2000,AGGREGATE(15,6,(ROW(海运报价!$C$2:$C$2000)-ROW(海运报价!$C$2)+1)/((海运报价!$D$2:$D$2000=$BE5)*(海运报价!$E$2:$E$2000=$BF5)),6)),"")) | BU5: =IF(OR($BE5="",$BF5=""),"",IFERROR(INDEX(海运报价!$C$2:$C$2000,AGGREGATE(15,6,(ROW(海运报价!$C$2:$C$2000)-ROW(海运报价!$C$2)+1)/((海运报价!$D$2:$D$2000=$BE5)*(海运报价!$E$2:$E$2000=$BF5)),7)),"")) | BV5: =IF(OR($BE5="",$BF5=""),"",IFERROR(INDEX(海运报价!$C$2:$C$2000,AGGREGATE(15,6,(ROW(海运报价!$C$2:$C$2000)-ROW(海运报价!$C$2)+1)/((海运报价!$D$2:$D$2000=$BE5)*(海运报价!$E$2:$E$2000=$BF5)),8)),"")) | BW5: =IF(OR($BE5="",$BF5=""),"",IFERROR(INDEX(海运报价!$C$2:$C$2000,AGGREGATE(15,6,(ROW(海运报价!$C$2:$C$2000)-ROW(海运报价!$C$2)+1)/((海运报价!$D$2:$D$2000=$BE5)*(海运报价!$E$2:$E$2000=$BF5)),9)),"")) | BX5: =IF(OR($BE5="",$BF5=""),"",IFERROR(INDEX(海运报价!$C$2:$C$2000,AGGREGATE(15,6,(ROW(海运报价!$C$2:$C$2000)-ROW(海运报价!$C$2)+1)/((海运报价!$D$2:$D$2000=$BE5)*(海运报价!$E$2:$E$2000=$BF5)),10)),"")) | BY5: =IF(OR($BE5="",$BF5=""),"",IFERROR(INDEX(海运报价!$C$2:$C$2000,AGGREGATE(15,6,(ROW(海运报价!$C$2:$C$2000)-ROW(海运报价!$C$2)+1)/((海运报价!$D$2:$D$2000=$BE5)*(海运报价!$E$2:$E$2000=$BF5)),11)),"")) | BZ5: =IF(OR($BE5="",$BF5=""),"",IFERROR(INDEX(海运报价!$C$2:$C$2000,AGGREGATE(15,6,(ROW(海运报价!$C$2:$C$2000)-ROW(海运报价!$C$2)+1)/((海运报价!$D$2:$D$2000=$BE5)*(海运报价!$E$2:$E$2000=$BF5)),12)),"")) | CA5: =IF(OR($BE5="",$BF5=""),"",IFERROR(INDEX(海运报价!$C$2:$C$2000,AGGREGATE(15,6,(ROW(海运报价!$C$2:$C$2000)-ROW(海运报价!$C$2)+1)/((海运报价!$D$2:$D$2000=$BE5)*(海运报价!$E$2:$E$2000=$BF5)),13)),"")) | CB5: =IF(OR($BE5="",$BF5=""),"",IFERROR(INDEX(海运报价!$C$2:$C$2000,AGGREGATE(15,6,(ROW(海运报价!$C$2:$C$2000)-ROW(海运报价!$C$2)+1)/((海运报价!$D$2:$D$2000=$BE5)*(海运报价!$E$2:$E$2000=$BF5)),14)),"")) | CC5: =IF(OR($BE5="",$BF5=""),"",IFERROR(INDEX(海运报价!$C$2:$C$2000,AGGREGATE(15,6,(ROW(海运报价!$C$2:$C$2000)-ROW(海运报价!$C$2)+1)/((海运报价!$D$2:$D$2000=$BE5)*(海运报价!$E$2:$E$2000=$BF5)),15)),"")) | CD5: =IF(OR(X5="",M5=""),"",X5+IF(OR(AA5="",M5=""),0,AA5/M5)+IF(AB5="",0,AB5)+IF(AI5="",0,AI5)+IF(Z5="",0,Z5)) | CE5: =I5+J5+K5+L5+AG5
C6: 2'6' | D6: =IF(C6="","",VLOOKUP($C6,箱规!$A$2:$S$23,9,FALSE)) | G6: =IF(OR(CD6="",CE6="",CE6>=1,X6=""),"",ROUNDUP((CD6-0.13*X6/1.13)/(1-CE6),2)) | H6: =IF(OR(CD6="",CE6="",X6=""),"",IF((1-CE6-参数!$B$16)<=0,"费率过高",ROUND((CD6-0.13*X6/1.13)/(1-CE6-参数!$B$16),2))) | I6: 0.15 | J6: 0.07 | K6: 0.15 | L6: 0.01 | M6: =参数!$B$2 | N6: =IF(C6="","",VLOOKUP($C6,箱规!$A$2:$S$23,14,FALSE)) | O6: =IF(C6="","",VLOOKUP($C6,箱规!$A$2:$S$23,5,FALSE)) | P6: =IF(C6="","",VLOOKUP($C6,箱规!$A$2:$S$23,6,FALSE)) | Q6: =IF(C6="","",VLOOKUP($C6,箱规!$A$2:$S$23,7,FALSE)) | R6: =IF(OR(N6="",O6="",P6="",Q6=""),"",MAX(N6*FBA规则!$B$6,(O6/FBA规则!$B$5)*(P6/FBA规则!$B$5)*(Q6/FBA规则!$B$5)/FBA规则!$B$7)) | S6: =IF(R6="","",IF(AND(N6*FBA规则!$B$6<=1,MAX(O6,P6,Q6)/FBA规则!$B$5<=15,MEDIAN(O6,P6,Q6)/FBA规则!$B$5<=12,MIN(O6,P6,Q6)/FBA规则!$B$5<=0.75),"小标准",IF(AND(R6<=20,MAX(O6,P6,Q6)/FBA规则!$B$5<=18,MEDIAN(O6,P6,Q6)/FBA规则!$B$5<=14,MIN(O6,P6,Q6)/FBA规则!$B$5<=8),"大标准",IF(AND(R6<=50,MAX(O6,P6,Q6)/FBA规则!$B$5<=59,MEDIAN(O6,P6,Q6)/FBA规则!$B$5<=33,MIN(O6,P6,Q6)/FBA规则!$B$5<=33,T6<=130),"大件",IF(R6<=50,"超大0-50lb",IF(R6<=70,"超大50-70lb",IF(R6<=150,"超大70-150lb","超大150lb+"))))))) | T6: =IF(OR(O6="",P6="",Q6=""),"",MAX(O6,P6,Q6)/FBA规则!$B$5+2*((MEDIAN(O6,P6,Q6)+MIN(O6,P6,Q6))/FBA规则!$B$5)) | U6: =参数!$B$15 | V6: =IF(OR(C6="",U6=""),"",(IF(OR(VLOOKUP($C6,箱规!$A$2:$S$23,4,FALSE)="",VLOOKUP($C6,箱规!$A$2:$S$23,4,FALSE)=0),VLOOKUP($C6,箱规!$A$2:$S$23,2,FALSE)*VLOOKUP($C6,箱规!$A$2:$S$23,3,FALSE)/10000,VLOOKUP($C6,箱规!$A$2:$S$23,4,FALSE)))*U6) | X6: =IF(AND(V6<>"",M6<>""),V6/M6,IF(AND(W6<>"",M6<>""),W6*1.13/M6,"")) | Y6: =IF(OR(X6="",G6=""),"",X6/G6) | AA6: =IF(OR(D6="",D6=0),"",IF(BG6="陆运",IF(BL6="",0,BL6)/D6,IF(BG6="海运",IF(BK6="",0,BK6)/D6,IF(BG6="海运+陆运",(IF(BK6="",0,BK6)+IF(BL6="",0,BL6))/D6,IF(BK6="",0,BK6)/D6)))) | AB6: =IF(OR(S6="",R6="",参数!$B$23=""),"",IF(S6="小标准",IFERROR(INDEX(FBA规则!$B$58:$C$65,MATCH(N6*FBA规则!$B$6*16,FBA规则!$A$58:$A$65,1),IF(参数!$B$23="旺季",2,1)),INDEX(FBA规则!$B$65:$C$65,1,IF(参数!$B$23="旺季",2,1))),IF(S6="大标准",IF(R6<=3,IFERROR(INDEX(FBA规则!$B$35:$C$46,MATCH(R6,FBA规则!$A$35:$A$46,1),IF(参数!$B$23="旺季",2,1)),INDEX(FBA规则!$B$46:$C$46,1,IF(参数!$B$23="旺季",2,1))),INDEX(FBA规则!$B$47:$C$47,1,IF(参数!$B$23="旺季",2,1))+FBA规则!$D$47*CEILING((R6-3)*4,1)),IF(S6="大件",INDEX(FBA规则!$B$50:$C$50,1,IF(参数!$B$23="旺季",2,1))+FBA规则!$D$50*MAX(0,CEILING(R6,1)-1),IF(S6="超大0-50lb",INDEX(FBA规则!$B$51:$C$51,1,IF(参数!$B$23="旺季",2,1))+FBA规则!$D$51*MAX(0,CEILING(R6,1)-1),IF(S6="超大50-70lb",INDEX(FBA规则!$B$52:$C$52,1,IF(参数!$B$23="旺季",2,1))+FBA规则!$D$52*MAX(0,R6-FBA规则!$F$52),IF(S6="超大70-150lb",INDEX(FBA规则!$B$53:$C$53,1,IF(参数!$B$23="旺季",2,1))+FBA规则!$D$53*MAX(0,R6-FBA规则!$F$53),INDEX(FBA规则!$B$54:$C$54,1,IF(参数!$B$23="旺季",2,1))+FBA规则!$D$54*MAX(0,R6-FBA规则!$F$54)))))))) | AC6: =IF(OR(G6="",I6=""),"",G6*I6) | AD6: =IF(OR(G6="",J6=""),"",G6*J6) | AE6: =IF(OR(G6="",K6=""),"",G6*K6) | AF6: =IF(OR(G6="",L6=""),"",G6*L6) | AG6: 0.02 | AH6: =IF(OR(G6="",AG6=""),"",G6*AG6) | AJ6: =IF(X6="","",X6+IF(OR(AA6="",M6=""),0,AA6/M6)+SUM(AB6:AF6)+IF(AH6="",0,AH6)+IF(AI6="",0,AI6)) | AK6: =IF(X6="","",0.13*X6/1.13) | AL6: =IF(OR(G6="",AJ6=""),"",G6+AK6-AJ6) | AM6: =IF(OR(AL6="",G6=""),"",AL6/G6) | AN6: =IF(OR(X6="",H6=""),"",X6/H6) | AP6: =AA6 | AQ6: =IF(OR(S6="",R6="",参数!$B$23=""),"",IF(S6="小标准",IFERROR(INDEX(FBA规则!$B$58:$C$65,MATCH(N6*FBA规则!$B$6*16,FBA规则!$A$58:$A$65,1),IF(参数!$B$23="旺季",2,1)),INDEX(FBA规则!$B$65:$C$65,1,IF(参数!$B$23="旺季",2,1))),IF(S6="大标准",IF(R6<=3,IFERROR(INDEX(FBA规则!$B$35:$C$46,MATCH(R6,FBA规则!$A$35:$A$46,1),IF(参数!$B$23="旺季",2,1)),INDEX(FBA规则!$B$46:$C$46,1,IF(参数!$B$23="旺季",2,1))),INDEX(FBA规则!$B$47:$C$47,1,IF(参数!$B$23="旺季",2,1))+FBA规则!$D$47*CEILING((R6-3)*4,1)),IF(S6="大件",INDEX(FBA规则!$B$50:$C$50,1,IF(参数!$B$23="旺季",2,1))+FBA规则!$D$50*MAX(0,CEILING(R6,1)-1),IF(S6="超大0-50lb",INDEX(FBA规则!$B$51:$C$51,1,IF(参数!$B$23="旺季",2,1))+FBA规则!$D$51*MAX(0,CEILING(R6,1)-1),IF(S6="超大50-70lb",INDEX(FBA规则!$B$52:$C$52,1,IF(参数!$B$23="旺季",2,1))+FBA规则!$D$52*MAX(0,R6-FBA规则!$F$52),IF(S6="超大70-150lb",INDEX(FBA规则!$B$53:$C$53,1,IF(参数!$B$23="旺季",2,1))+FBA规则!$D$53*MAX(0,R6-FBA规则!$F$53),INDEX(FBA规则!$B$54:$C$54,1,IF(参数!$B$23="旺季",2,1))+FBA规则!$D$54*MAX(0,R6-FBA规则!$F$54)))))))) | AR6: =IF(OR(H6="",I6=""),"",H6*I6) | AS6: =IF(OR(H6="",J6=""),"",H6*J6) | AT6: =IF(OR(H6="",K6=""),"",H6*K6) | AU6: =IF(OR(H6="",L6=""),"",H6*L6) | AV6: 0.02 | AW6: =IF(OR(H6="",AV6=""),"",H6*AV6) | AY6: =IF(X6="","",X6+IF(OR(AP6="",M6=""),0,AP6/M6)+SUM(AQ6:AU6)+IF(AW6="",0,AW6)+IF(AX6="",0,AX6)) | AZ6: =IF(X6="","",0.13*X6/1.13) | BA6: =IF(OR(H6="",AY6=""),"",H6+AZ6-AY6) | BB6: =IF(OR(BA6="",H6=""),"",BA6/H6) | BC6: =IF(OR(H6="",AY6=""),"",H6-AY6) | BD6: =IF(OR(BC6="",H6=""),"",BC6/H6) | BE6: 义乌 | BF6: ABE8 | BG6: 海运 | BH6: （最低价） | BI6: =IF(OR(BE6="",BF6=""),"",IF(AND(BH6<>"",BH6<>"（最低价）"),IFERROR(IF(SUMIFS(海运报价!$F$2:$F$2000,海运报价!$C$2:$C$2000,BH6,海运报价!$D$2:$D$2000,BE6,海运报价!$E$2:$E$2000,BF6)=0,"",SUMIFS(海运报价!$F$2:$F$2000,海运报价!$C$2:$C$2000,BH6,海运报价!$D$2:$D$2000,BE6,海运报价!$E$2:$E$2000,BF6)),""),IFERROR(IF(SUMIFS(海运下拉!$H$2:$H$311,海运下拉!$F$2:$F$311,BE6,海运下拉!$G$2:$G$311,BF6)=0,"",SUMIFS(海运下拉!$H$2:$H$311,海运下拉!$F$2:$F$311,BE6,海运下拉!$G$2:$G$311,BF6)),""))) | BJ6: =IF(C6="","",VLOOKUP($C6,箱规!$A$2:$S$23,18,FALSE)) | BK6: =IF(OR(BI6="",BJ6=""),"",BJ6*(BI6+IF(AND(BH6<>"",BH6<>"（最低价）"),IFERROR(AVERAGEIFS(海运报价!$H$2:$H$2000,海运报价!$C$2:$C$2000,BH6,海运报价!$D$2:$D$2000,BE6,海运报价!$E$2:$E$2000,BF6),0),IFERROR(SUMIFS(海运下拉!$J$2:$J$311,海运下拉!$F$2:$F$311,BE6,海运下拉!$G$2:$G$311,BF6),0)))) | BM6: =IF(OR(BE6="",BF6=""),"请选起运地+FBA仓",IF(AND(AND(BH6<>"",BH6<>"（最低价）"),BI6=""),"⚠该渠道不服务此仓：请重选渠道，或选「（最低价）」",IF(BI6="","无报价：请换起运地/仓库",IF(AND(BH6<>"",BH6<>"（最低价）"),"按你选的渠道「"&BH6&"」计价","按最低价「"&IFERROR(SUMIFS(海运下拉!$I$2:$I$311,海运下拉!$F$2:$F$311,BE6,海运下拉!$G$2:$G$311,BF6),"")&"」（渠道默认最低价）")))) | BO6: =IF(OR($BE6="",$BF6=""),"",IFERROR(INDEX(海运报价!$C$2:$C$2000,AGGREGATE(15,6,(ROW(海运报价!$C$2:$C$2000)-ROW(海运报价!$C$2)+1)/((海运报价!$D$2:$D$2000=$BE6)*(海运报价!$E$2:$E$2000=$BF6)),1)),"")) | BP6: =IF(OR($BE6="",$BF6=""),"",IFERROR(INDEX(海运报价!$C$2:$C$2000,AGGREGATE(15,6,(ROW(海运报价!$C$2:$C$2000)-ROW(海运报价!$C$2)+1)/((海运报价!$D$2:$D$2000=$BE6)*(海运报价!$E$2:$E$2000=$BF6)),2)),"")) | BQ6: =IF(OR($BE6="",$BF6=""),"",IFERROR(INDEX(海运报价!$C$2:$C$2000,AGGREGATE(15,6,(ROW(海运报价!$C$2:$C$2000)-ROW(海运报价!$C$2)+1)/((海运报价!$D$2:$D$2000=$BE6)*(海运报价!$E$2:$E$2000=$BF6)),3)),"")) | BR6: =IF(OR($BE6="",$BF6=""),"",IFERROR(INDEX(海运报价!$C$2:$C$2000,AGGREGATE(15,6,(ROW(海运报价!$C$2:$C$2000)-ROW(海运报价!$C$2)+1)/((海运报价!$D$2:$D$2000=$BE6)*(海运报价!$E$2:$E$2000=$BF6)),4)),"")) | BS6: =IF(OR($BE6="",$BF6=""),"",IFERROR(INDEX(海运报价!$C$2:$C$2000,AGGREGATE(15,6,(ROW(海运报价!$C$2:$C$2000)-ROW(海运报价!$C$2)+1)/((海运报价!$D$2:$D$2000=$BE6)*(海运报价!$E$2:$E$2000=$BF6)),5)),"")) | BT6: =IF(OR($BE6="",$BF6=""),"",IFERROR(INDEX(海运报价!$C$2:$C$2000,AGGREGATE(15,6,(ROW(海运报价!$C$2:$C$2000)-ROW(海运报价!$C$2)+1)/((海运报价!$D$2:$D$2000=$BE6)*(海运报价!$E$2:$E$2000=$BF6)),6)),"")) | BU6: =IF(OR($BE6="",$BF6=""),"",IFERROR(INDEX(海运报价!$C$2:$C$2000,AGGREGATE(15,6,(ROW(海运报价!$C$2:$C$2000)-ROW(海运报价!$C$2)+1)/((海运报价!$D$2:$D$2000=$BE6)*(海运报价!$E$2:$E$2000=$BF6)),7)),"")) | BV6: =IF(OR($BE6="",$BF6=""),"",IFERROR(INDEX(海运报价!$C$2:$C$2000,AGGREGATE(15,6,(ROW(海运报价!$C$2:$C$2000)-ROW(海运报价!$C$2)+1)/((海运报价!$D$2:$D$2000=$BE6)*(海运报价!$E$2:$E$2000=$BF6)),8)),"")) | BW6: =IF(OR($BE6="",$BF6=""),"",IFERROR(INDEX(海运报价!$C$2:$C$2000,AGGREGATE(15,6,(ROW(海运报价!$C$2:$C$2000)-ROW(海运报价!$C$2)+1)/((海运报价!$D$2:$D$2000=$BE6)*(海运报价!$E$2:$E$2000=$BF6)),9)),"")) | BX6: =IF(OR($BE6="",$BF6=""),"",IFERROR(INDEX(海运报价!$C$2:$C$2000,AGGREGATE(15,6,(ROW(海运报价!$C$2:$C$2000)-ROW(海运报价!$C$2)+1)/((海运报价!$D$2:$D$2000=$BE6)*(海运报价!$E$2:$E$2000=$BF6)),10)),"")) | BY6: =IF(OR($BE6="",$BF6=""),"",IFERROR(INDEX(海运报价!$C$2:$C$2000,AGGREGATE(15,6,(ROW(海运报价!$C$2:$C$2000)-ROW(海运报价!$C$2)+1)/((海运报价!$D$2:$D$2000=$BE6)*(海运报价!$E$2:$E$2000=$BF6)),11)),"")) | BZ6: =IF(OR($BE6="",$BF6=""),"",IFERROR(INDEX(海运报价!$C$2:$C$2000,AGGREGATE(15,6,(ROW(海运报价!$C$2:$C$2000)-ROW(海运报价!$C$2)+1)/((海运报价!$D$2:$D$2000=$BE6)*(海运报价!$E$2:$E$2000=$BF6)),12)),"")) | CA6: =IF(OR($BE6="",$BF6=""),"",IFERROR(INDEX(海运报价!$C$2:$C$2000,AGGREGATE(15,6,(ROW(海运报价!$C$2:$C$2000)-ROW(海运报价!$C$2)+1)/((海运报价!$D$2:$D$2000=$BE6)*(海运报价!$E$2:$E$2000=$BF6)),13)),"")) | CB6: =IF(OR($BE6="",$BF6=""),"",IFERROR(INDEX(海运报价!$C$2:$C$2000,AGGREGATE(15,6,(ROW(海运报价!$C$2:$C$2000)-ROW(海运报价!$C$2)+1)/((海运报价!$D$2:$D$2000=$BE6)*(海运报价!$E$2:$E$2000=$BF6)),14)),"")) | CC6: =IF(OR($BE6="",$BF6=""),"",IFERROR(INDEX(海运报价!$C$2:$C$2000,AGGREGATE(15,6,(ROW(海运报价!$C$2:$C$2000)-ROW(海运报价!$C$2)+1)/((海运报价!$D$2:$D$2000=$BE6)*(海运报价!$E$2:$E$2000=$BF6)),15)),"")) | CD6: =IF(OR(X6="",M6=""),"",X6+IF(OR(AA6="",M6=""),0,AA6/M6)+IF(AB6="",0,AB6)+IF(AI6="",0,AI6)+IF(Z6="",0,Z6)) | CE6: =I6+J6+K6+L6+AG6
C7: 2'8' | D7: =IF(C7="","",VLOOKUP($C7,箱规!$A$2:$S$23,9,FALSE)) | G7: =IF(OR(CD7="",CE7="",CE7>=1,X7=""),"",ROUNDUP((CD7-0.13*X7/1.13)/(1-CE7),2)) | H7: =IF(OR(CD7="",CE7="",X7=""),"",IF((1-CE7-参数!$B$16)<=0,"费率过高",ROUND((CD7-0.13*X7/1.13)/(1-CE7-参数!$B$16),2))) | I7: 0.15 | J7: 0.07 | K7: 0.15 | L7: 0.01 | M7: =参数!$B$2 | N7: =IF(C7="","",VLOOKUP($C7,箱规!$A$2:$S$23,14,FALSE)) | O7: =IF(C7="","",VLOOKUP($C7,箱规!$A$2:$S$23,5,FALSE)) | P7: =IF(C7="","",VLOOKUP($C7,箱规!$A$2:$S$23,6,FALSE)) | Q7: =IF(C7="","",VLOOKUP($C7,箱规!$A$2:$S$23,7,FALSE)) | R7: =IF(OR(N7="",O7="",P7="",Q7=""),"",MAX(N7*FBA规则!$B$6,(O7/FBA规则!$B$5)*(P7/FBA规则!$B$5)*(Q7/FBA规则!$B$5)/FBA规则!$B$7)) | S7: =IF(R7="","",IF(AND(N7*FBA规则!$B$6<=1,MAX(O7,P7,Q7)/FBA规则!$B$5<=15,MEDIAN(O7,P7,Q7)/FBA规则!$B$5<=12,MIN(O7,P7,Q7)/FBA规则!$B$5<=0.75),"小标准",IF(AND(R7<=20,MAX(O7,P7,Q7)/FBA规则!$B$5<=18,MEDIAN(O7,P7,Q7)/FBA规则!$B$5<=14,MIN(O7,P7,Q7)/FBA规则!$B$5<=8),"大标准",IF(AND(R7<=50,MAX(O7,P7,Q7)/FBA规则!$B$5<=59,MEDIAN(O7,P7,Q7)/FBA规则!$B$5<=33,MIN(O7,P7,Q7)/FBA规则!$B$5<=33,T7<=130),"大件",IF(R7<=50,"超大0-50lb",IF(R7<=70,"超大50-70lb",IF(R7<=150,"超大70-150lb","超大150lb+"))))))) | T7: =IF(OR(O7="",P7="",Q7=""),"",MAX(O7,P7,Q7)/FBA规则!$B$5+2*((MEDIAN(O7,P7,Q7)+MIN(O7,P7,Q7))/FBA规则!$B$5)) | U7: =参数!$B$15 | V7: =IF(OR(C7="",U7=""),"",(IF(OR(VLOOKUP($C7,箱规!$A$2:$S$23,4,FALSE)="",VLOOKUP($C7,箱规!$A$2:$S$23,4,FALSE)=0),VLOOKUP($C7,箱规!$A$2:$S$23,2,FALSE)*VLOOKUP($C7,箱规!$A$2:$S$23,3,FALSE)/10000,VLOOKUP($C7,箱规!$A$2:$S$23,4,FALSE)))*U7) | X7: =IF(AND(V7<>"",M7<>""),V7/M7,IF(AND(W7<>"",M7<>""),W7*1.13/M7,"")) | Y7: =IF(OR(X7="",G7=""),"",X7/G7) | AA7: =IF(OR(D7="",D7=0),"",IF(BG7="陆运",IF(BL7="",0,BL7)/D7,IF(BG7="海运",IF(BK7="",0,BK7)/D7,IF(BG7="海运+陆运",(IF(BK7="",0,BK7)+IF(BL7="",0,BL7))/D7,IF(BK7="",0,BK7)/D7)))) | AB7: =IF(OR(S7="",R7="",参数!$B$23=""),"",IF(S7="小标准",IFERROR(INDEX(FBA规则!$B$58:$C$65,MATCH(N7*FBA规则!$B$6*16,FBA规则!$A$58:$A$65,1),IF(参数!$B$23="旺季",2,1)),INDEX(FBA规则!$B$65:$C$65,1,IF(参数!$B$23="旺季",2,1))),IF(S7="大标准",IF(R7<=3,IFERROR(INDEX(FBA规则!$B$35:$C$46,MATCH(R7,FBA规则!$A$35:$A$46,1),IF(参数!$B$23="旺季",2,1)),INDEX(FBA规则!$B$46:$C$46,1,IF(参数!$B$23="旺季",2,1))),INDEX(FBA规则!$B$47:$C$47,1,IF(参数!$B$23="旺季",2,1))+FBA规则!$D$47*CEILING((R7-3)*4,1)),IF(S7="大件",INDEX(FBA规则!$B$50:$C$50,1,IF(参数!$B$23="旺季",2,1))+FBA规则!$D$50*MAX(0,CEILING(R7,1)-1),IF(S7="超大0-50lb",INDEX(FBA规则!$B$51:$C$51,1,IF(参数!$B$23="旺季",2,1))+FBA规则!$D$51*MAX(0,CEILING(R7,1)-1),IF(S7="超大50-70lb",INDEX(FBA规则!$B$52:$C$52,1,IF(参数!$B$23="旺季",2,1))+FBA规则!$D$52*MAX(0,R7-FBA规则!$F$52),IF(S7="超大70-150lb",INDEX(FBA规则!$B$53:$C$53,1,IF(参数!$B$23="旺季",2,1))+FBA规则!$D$53*MAX(0,R7-FBA规则!$F$53),INDEX(FBA规则!$B$54:$C$54,1,IF(参数!$B$23="旺季",2,1))+FBA规则!$D$54*MAX(0,R7-FBA规则!$F$54)))))))) | AC7: =IF(OR(G7="",I7=""),"",G7*I7) | AD7: =IF(OR(G7="",J7=""),"",G7*J7) | AE7: =IF(OR(G7="",K7=""),"",G7*K7) | AF7: =IF(OR(G7="",L7=""),"",G7*L7) | AG7: 0.02 | AH7: =IF(OR(G7="",AG7=""),"",G7*AG7) | AJ7: =IF(X7="","",X7+IF(OR(AA7="",M7=""),0,AA7/M7)+SUM(AB7:AF7)+IF(AH7="",0,AH7)+IF(AI7="",0,AI7)) | AK7: =IF(X7="","",0.13*X7/1.13) | AL7: =IF(OR(G7="",AJ7=""),"",G7+AK7-AJ7) | AM7: =IF(OR(AL7="",G7=""),"",AL7/G7) | AN7: =IF(OR(X7="",H7=""),"",X7/H7) | AP7: =AA7 | AQ7: =IF(OR(S7="",R7="",参数!$B$23=""),"",IF(S7="小标准",IFERROR(INDEX(FBA规则!$B$58:$C$65,MATCH(N7*FBA规则!$B$6*16,FBA规则!$A$58:$A$65,1),IF(参数!$B$23="旺季",2,1)),INDEX(FBA规则!$B$65:$C$65,1,IF(参数!$B$23="旺季",2,1))),IF(S7="大标准",IF(R7<=3,IFERROR(INDEX(FBA规则!$B$35:$C$46,MATCH(R7,FBA规则!$A$35:$A$46,1),IF(参数!$B$23="旺季",2,1)),INDEX(FBA规则!$B$46:$C$46,1,IF(参数!$B$23="旺季",2,1))),INDEX(FBA规则!$B$47:$C$47,1,IF(参数!$B$23="旺季",2,1))+FBA规则!$D$47*CEILING((R7-3)*4,1)),IF(S7="大件",INDEX(FBA规则!$B$50:$C$50,1,IF(参数!$B$23="旺季",2,1))+FBA规则!$D$50*MAX(0,CEILING(R7,1)-1),IF(S7="超大0-50lb",INDEX(FBA规则!$B$51:$C$51,1,IF(参数!$B$23="旺季",2,1))+FBA规则!$D$51*MAX(0,CEILING(R7,1)-1),IF(S7="超大50-70lb",INDEX(FBA规则!$B$52:$C$52,1,IF(参数!$B$23="旺季",2,1))+FBA规则!$D$52*MAX(0,R7-FBA规则!$F$52),IF(S7="超大70-150lb",INDEX(FBA规则!$B$53:$C$53,1,IF(参数!$B$23="旺季",2,1))+FBA规则!$D$53*MAX(0,R7-FBA规则!$F$53),INDEX(FBA规则!$B$54:$C$54,1,IF(参数!$B$23="旺季",2,1))+FBA规则!$D$54*MAX(0,R7-FBA规则!$F$54)))))))) | AR7: =IF(OR(H7="",I7=""),"",H7*I7) | AS7: =IF(OR(H7="",J7=""),"",H7*J7) | AT7: =IF(OR(H7="",K7=""),"",H7*K7) | AU7: =IF(OR(H7="",L7=""),"",H7*L7) | AV7: 0.02 | AW7: =IF(OR(H7="",AV7=""),"",H7*AV7) | AY7: =IF(X7="","",X7+IF(OR(AP7="",M7=""),0,AP7/M7)+SUM(AQ7:AU7)+IF(AW7="",0,AW7)+IF(AX7="",0,AX7)) | AZ7: =IF(X7="","",0.13*X7/1.13) | BA7: =IF(OR(H7="",AY7=""),"",H7+AZ7-AY7) | BB7: =IF(OR(BA7="",H7=""),"",BA7/H7) | BC7: =IF(OR(H7="",AY7=""),"",H7-AY7) | BD7: =IF(OR(BC7="",H7=""),"",BC7/H7) | BE7: 义乌 | BF7: ABE8 | BG7: 海运 | BH7: （最低价） | BI7: =IF(OR(BE7="",BF7=""),"",IF(AND(BH7<>"",BH7<>"（最低价）"),IFERROR(IF(SUMIFS(海运报价!$F$2:$F$2000,海运报价!$C$2:$C$2000,BH7,海运报价!$D$2:$D$2000,BE7,海运报价!$E$2:$E$2000,BF7)=0,"",SUMIFS(海运报价!$F$2:$F$2000,海运报价!$C$2:$C$2000,BH7,海运报价!$D$2:$D$2000,BE7,海运报价!$E$2:$E$2000,BF7)),""),IFERROR(IF(SUMIFS(海运下拉!$H$2:$H$311,海运下拉!$F$2:$F$311,BE7,海运下拉!$G$2:$G$311,BF7)=0,"",SUMIFS(海运下拉!$H$2:$H$311,海运下拉!$F$2:$F$311,BE7,海运下拉!$G$2:$G$311,BF7)),""))) | BJ7: =IF(C7="","",VLOOKUP($C7,箱规!$A$2:$S$23,18,FALSE)) | BK7: =IF(OR(BI7="",BJ7=""),"",BJ7*(BI7+IF(AND(BH7<>"",BH7<>"（最低价）"),IFERROR(AVERAGEIFS(海运报价!$H$2:$H$2000,海运报价!$C$2:$C$2000,BH7,海运报价!$D$2:$D$2000,BE7,海运报价!$E$2:$E$2000,BF7),0),IFERROR(SUMIFS(海运下拉!$J$2:$J$311,海运下拉!$F$2:$F$311,BE7,海运下拉!$G$2:$G$311,BF7),0)))) | BM7: =IF(OR(BE7="",BF7=""),"请选起运地+FBA仓",IF(AND(AND(BH7<>"",BH7<>"（最低价）"),BI7=""),"⚠该渠道不服务此仓：请重选渠道，或选「（最低价）」",IF(BI7="","无报价：请换起运地/仓库",IF(AND(BH7<>"",BH7<>"（最低价）"),"按你选的渠道「"&BH7&"」计价","按最低价「"&IFERROR(SUMIFS(海运下拉!$I$2:$I$311,海运下拉!$F$2:$F$311,BE7,海运下拉!$G$2:$G$311,BF7),"")&"」（渠道默认最低价）")))) | BO7: =IF(OR($BE7="",$BF7=""),"",IFERROR(INDEX(海运报价!$C$2:$C$2000,AGGREGATE(15,6,(ROW(海运报价!$C$2:$C$2000)-ROW(海运报价!$C$2)+1)/((海运报价!$D$2:$D$2000=$BE7)*(海运报价!$E$2:$E$2000=$BF7)),1)),"")) | BP7: =IF(OR($BE7="",$BF7=""),"",IFERROR(INDEX(海运报价!$C$2:$C$2000,AGGREGATE(15,6,(ROW(海运报价!$C$2:$C$2000)-ROW(海运报价!$C$2)+1)/((海运报价!$D$2:$D$2000=$BE7)*(海运报价!$E$2:$E$2000=$BF7)),2)),"")) | BQ7: =IF(OR($BE7="",$BF7=""),"",IFERROR(INDEX(海运报价!$C$2:$C$2000,AGGREGATE(15,6,(ROW(海运报价!$C$2:$C$2000)-ROW(海运报价!$C$2)+1)/((海运报价!$D$2:$D$2000=$BE7)*(海运报价!$E$2:$E$2000=$BF7)),3)),"")) | BR7: =IF(OR($BE7="",$BF7=""),"",IFERROR(INDEX(海运报价!$C$2:$C$2000,AGGREGATE(15,6,(ROW(海运报价!$C$2:$C$2000)-ROW(海运报价!$C$2)+1)/((海运报价!$D$2:$D$2000=$BE7)*(海运报价!$E$2:$E$2000=$BF7)),4)),"")) | BS7: =IF(OR($BE7="",$BF7=""),"",IFERROR(INDEX(海运报价!$C$2:$C$2000,AGGREGATE(15,6,(ROW(海运报价!$C$2:$C$2000)-ROW(海运报价!$C$2)+1)/((海运报价!$D$2:$D$2000=$BE7)*(海运报价!$E$2:$E$2000=$BF7)),5)),"")) | BT7: =IF(OR($BE7="",$BF7=""),"",IFERROR(INDEX(海运报价!$C$2:$C$2000,AGGREGATE(15,6,(ROW(海运报价!$C$2:$C$2000)-ROW(海运报价!$C$2)+1)/((海运报价!$D$2:$D$2000=$BE7)*(海运报价!$E$2:$E$2000=$BF7)),6)),"")) | BU7: =IF(OR($BE7="",$BF7=""),"",IFERROR(INDEX(海运报价!$C$2:$C$2000,AGGREGATE(15,6,(ROW(海运报价!$C$2:$C$2000)-ROW(海运报价!$C$2)+1)/((海运报价!$D$2:$D$2000=$BE7)*(海运报价!$E$2:$E$2000=$BF7)),7)),"")) | BV7: =IF(OR($BE7="",$BF7=""),"",IFERROR(INDEX(海运报价!$C$2:$C$2000,AGGREGATE(15,6,(ROW(海运报价!$C$2:$C$2000)-ROW(海运报价!$C$2)+1)/((海运报价!$D$2:$D$2000=$BE7)*(海运报价!$E$2:$E$2000=$BF7)),8)),"")) | BW7: =IF(OR($BE7="",$BF7=""),"",IFERROR(INDEX(海运报价!$C$2:$C$2000,AGGREGATE(15,6,(ROW(海运报价!$C$2:$C$2000)-ROW(海运报价!$C$2)+1)/((海运报价!$D$2:$D$2000=$BE7)*(海运报价!$E$2:$E$2000=$BF7)),9)),"")) | BX7: =IF(OR($BE7="",$BF7=""),"",IFERROR(INDEX(海运报价!$C$2:$C$2000,AGGREGATE(15,6,(ROW(海运报价!$C$2:$C$2000)-ROW(海运报价!$C$2)+1)/((海运报价!$D$2:$D$2000=$BE7)*(海运报价!$E$2:$E$2000=$BF7)),10)),"")) | BY7: =IF(OR($BE7="",$BF7=""),"",IFERROR(INDEX(海运报价!$C$2:$C$2000,AGGREGATE(15,6,(ROW(海运报价!$C$2:$C$2000)-ROW(海运报价!$C$2)+1)/((海运报价!$D$2:$D$2000=$BE7)*(海运报价!$E$2:$E$2000=$BF7)),11)),"")) | BZ7: =IF(OR($BE7="",$BF7=""),"",IFERROR(INDEX(海运报价!$C$2:$C$2000,AGGREGATE(15,6,(ROW(海运报价!$C$2:$C$2000)-ROW(海运报价!$C$2)+1)/((海运报价!$D$2:$D$2000=$BE7)*(海运报价!$E$2:$E$2000=$BF7)),12)),"")) | CA7: =IF(OR($BE7="",$BF7=""),"",IFERROR(INDEX(海运报价!$C$2:$C$2000,AGGREGATE(15,6,(ROW(海运报价!$C$2:$C$2000)-ROW(海运报价!$C$2)+1)/((海运报价!$D$2:$D$2000=$BE7)*(海运报价!$E$2:$E$2000=$BF7)),13)),"")) | CB7: =IF(OR($BE7="",$BF7=""),"",IFERROR(INDEX(海运报价!$C$2:$C$2000,AGGREGATE(15,6,(ROW(海运报价!$C$2:$C$2000)-ROW(海运报价!$C$2)+1)/((海运报价!$D$2:$D$2000=$BE7)*(海运报价!$E$2:$E$2000=$BF7)),14)),"")) | CC7: =IF(OR($BE7="",$BF7=""),"",IFERROR(INDEX(海运报价!$C$2:$C$2000,AGGREGATE(15,6,(ROW(海运报价!$C$2:$C$2000)-ROW(海运报价!$C$2)+1)/((海运报价!$D$2:$D$2000=$BE7)*(海运报价!$E$2:$E$2000=$BF7)),15)),"")) | CD7: =IF(OR(X7="",M7=""),"",X7+IF(OR(AA7="",M7=""),0,AA7/M7)+IF(AB7="",0,AB7)+IF(AI7="",0,AI7)+IF(Z7="",0,Z7)) | CE7: =I7+J7+K7+L7+AG7
C8: 2'10' | D8: =IF(C8="","",VLOOKUP($C8,箱规!$A$2:$S$23,9,FALSE)) | G8: =IF(OR(CD8="",CE8="",CE8>=1,X8=""),"",ROUNDUP((CD8-0.13*X8/1.13)/(1-CE8),2)) | H8: =IF(OR(CD8="",CE8="",X8=""),"",IF((1-CE8-参数!$B$16)<=0,"费率过高",ROUND((CD8-0.13*X8/1.13)/(1-CE8-参数!$B$16),2))) | I8: 0.15 | J8: 0.07 | K8: 0.15 | L8: 0.01 | M8: =参数!$B$2 | N8: =IF(C8="","",VLOOKUP($C8,箱规!$A$2:$S$23,14,FALSE)) | O8: =IF(C8="","",VLOOKUP($C8,箱规!$A$2:$S$23,5,FALSE)) | P8: =IF(C8="","",VLOOKUP($C8,箱规!$A$2:$S$23,6,FALSE)) | Q8: =IF(C8="","",VLOOKUP($C8,箱规!$A$2:$S$23,7,FALSE)) | R8: =IF(OR(N8="",O8="",P8="",Q8=""),"",MAX(N8*FBA规则!$B$6,(O8/FBA规则!$B$5)*(P8/FBA规则!$B$5)*(Q8/FBA规则!$B$5)/FBA规则!$B$7)) | S8: =IF(R8="","",IF(AND(N8*FBA规则!$B$6<=1,MAX(O8,P8,Q8)/FBA规则!$B$5<=15,MEDIAN(O8,P8,Q8)/FBA规则!$B$5<=12,MIN(O8,P8,Q8)/FBA规则!$B$5<=0.75),"小标准",IF(AND(R8<=20,MAX(O8,P8,Q8)/FBA规则!$B$5<=18,MEDIAN(O8,P8,Q8)/FBA规则!$B$5<=14,MIN(O8,P8,Q8)/FBA规则!$B$5<=8),"大标准",IF(AND(R8<=50,MAX(O8,P8,Q8)/FBA规则!$B$5<=59,MEDIAN(O8,P8,Q8)/FBA规则!$B$5<=33,MIN(O8,P8,Q8)/FBA规则!$B$5<=33,T8<=130),"大件",IF(R8<=50,"超大0-50lb",IF(R8<=70,"超大50-70lb",IF(R8<=150,"超大70-150lb","超大150lb+"))))))) | T8: =IF(OR(O8="",P8="",Q8=""),"",MAX(O8,P8,Q8)/FBA规则!$B$5+2*((MEDIAN(O8,P8,Q8)+MIN(O8,P8,Q8))/FBA规则!$B$5)) | U8: =参数!$B$15 | V8: =IF(OR(C8="",U8=""),"",(IF(OR(VLOOKUP($C8,箱规!$A$2:$S$23,4,FALSE)="",VLOOKUP($C8,箱规!$A$2:$S$23,4,FALSE)=0),VLOOKUP($C8,箱规!$A$2:$S$23,2,FALSE)*VLOOKUP($C8,箱规!$A$2:$S$23,3,FALSE)/10000,VLOOKUP($C8,箱规!$A$2:$S$23,4,FALSE)))*U8) | X8: =IF(AND(V8<>"",M8<>""),V8/M8,IF(AND(W8<>"",M8<>""),W8*1.13/M8,"")) | Y8: =IF(OR(X8="",G8=""),"",X8/G8) | AA8: =IF(OR(D8="",D8=0),"",IF(BG8="陆运",IF(BL8="",0,BL8)/D8,IF(BG8="海运",IF(BK8="",0,BK8)/D8,IF(BG8="海运+陆运",(IF(BK8="",0,BK8)+IF(BL8="",0,BL8))/D8,IF(BK8="",0,BK8)/D8)))) | AB8: =IF(OR(S8="",R8="",参数!$B$23=""),"",IF(S8="小标准",IFERROR(INDEX(FBA规则!$B$58:$C$65,MATCH(N8*FBA规则!$B$6*16,FBA规则!$A$58:$A$65,1),IF(参数!$B$23="旺季",2,1)),INDEX(FBA规则!$B$65:$C$65,1,IF(参数!$B$23="旺季",2,1))),IF(S8="大标准",IF(R8<=3,IFERROR(INDEX(FBA规则!$B$35:$C$46,MATCH(R8,FBA规则!$A$35:$A$46,1),IF(参数!$B$23="旺季",2,1)),INDEX(FBA规则!$B$46:$C$46,1,IF(参数!$B$23="旺季",2,1))),INDEX(FBA规则!$B$47:$C$47,1,IF(参数!$B$23="旺季",2,1))+FBA规则!$D$47*CEILING((R8-3)*4,1)),IF(S8="大件",INDEX(FBA规则!$B$50:$C$50,1,IF(参数!$B$23="旺季",2,1))+FBA规则!$D$50*MAX(0,CEILING(R8,1)-1),IF(S8="超大0-50lb",INDEX(FBA规则!$B$51:$C$51,1,IF(参数!$B$23="旺季",2,1))+FBA规则!$D$51*MAX(0,CEILING(R8,1)-1),IF(S8="超大50-70lb",INDEX(FBA规则!$B$52:$C$52,1,IF(参数!$B$23="旺季",2,1))+FBA规则!$D$52*MAX(0,R8-FBA规则!$F$52),IF(S8="超大70-150lb",INDEX(FBA规则!$B$53:$C$53,1,IF(参数!$B$23="旺季",2,1))+FBA规则!$D$53*MAX(0,R8-FBA规则!$F$53),INDEX(FBA规则!$B$54:$C$54,1,IF(参数!$B$23="旺季",2,1))+FBA规则!$D$54*MAX(0,R8-FBA规则!$F$54)))))))) | AC8: =IF(OR(G8="",I8=""),"",G8*I8) | AD8: =IF(OR(G8="",J8=""),"",G8*J8) | AE8: =IF(OR(G8="",K8=""),"",G8*K8) | AF8: =IF(OR(G8="",L8=""),"",G8*L8) | AG8: 0.02 | AH8: =IF(OR(G8="",AG8=""),"",G8*AG8) | AJ8: =IF(X8="","",X8+IF(OR(AA8="",M8=""),0,AA8/M8)+SUM(AB8:AF8)+IF(AH8="",0,AH8)+IF(AI8="",0,AI8)) | AK8: =IF(X8="","",0.13*X8/1.13) | AL8: =IF(OR(G8="",AJ8=""),"",G8+AK8-AJ8) | AM8: =IF(OR(AL8="",G8=""),"",AL8/G8) | AN8: =IF(OR(X8="",H8=""),"",X8/H8) | AP8: =AA8 | AQ8: =IF(OR(S8="",R8="",参数!$B$23=""),"",IF(S8="小标准",IFERROR(INDEX(FBA规则!$B$58:$C$65,MATCH(N8*FBA规则!$B$6*16,FBA规则!$A$58:$A$65,1),IF(参数!$B$23="旺季",2,1)),INDEX(FBA规则!$B$65:$C$65,1,IF(参数!$B$23="旺季",2,1))),IF(S8="大标准",IF(R8<=3,IFERROR(INDEX(FBA规则!$B$35:$C$46,MATCH(R8,FBA规则!$A$35:$A$46,1),IF(参数!$B$23="旺季",2,1)),INDEX(FBA规则!$B$46:$C$46,1,IF(参数!$B$23="旺季",2,1))),INDEX(FBA规则!$B$47:$C$47,1,IF(参数!$B$23="旺季",2,1))+FBA规则!$D$47*CEILING((R8-3)*4,1)),IF(S8="大件",INDEX(FBA规则!$B$50:$C$50,1,IF(参数!$B$23="旺季",2,1))+FBA规则!$D$50*MAX(0,CEILING(R8,1)-1),IF(S8="超大0-50lb",INDEX(FBA规则!$B$51:$C$51,1,IF(参数!$B$23="旺季",2,1))+FBA规则!$D$51*MAX(0,CEILING(R8,1)-1),IF(S8="超大50-70lb",INDEX(FBA规则!$B$52:$C$52,1,IF(参数!$B$23="旺季",2,1))+FBA规则!$D$52*MAX(0,R8-FBA规则!$F$52),IF(S8="超大70-150lb",INDEX(FBA规则!$B$53:$C$53,1,IF(参数!$B$23="旺季",2,1))+FBA规则!$D$53*MAX(0,R8-FBA规则!$F$53),INDEX(FBA规则!$B$54:$C$54,1,IF(参数!$B$23="旺季",2,1))+FBA规则!$D$54*MAX(0,R8-FBA规则!$F$54)))))))) | AR8: =IF(OR(H8="",I8=""),"",H8*I8) | AS8: =IF(OR(H8="",J8=""),"",H8*J8) | AT8: =IF(OR(H8="",K8=""),"",H8*K8) | AU8: =IF(OR(H8="",L8=""),"",H8*L8) | AV8: 0.02 | AW8: =IF(OR(H8="",AV8=""),"",H8*AV8) | AY8: =IF(X8="","",X8+IF(OR(AP8="",M8=""),0,AP8/M8)+SUM(AQ8:AU8)+IF(AW8="",0,AW8)+IF(AX8="",0,AX8)) | AZ8: =IF(X8="","",0.13*X8/1.13) | BA8: =IF(OR(H8="",AY8=""),"",H8+AZ8-AY8) | BB8: =IF(OR(BA8="",H8=""),"",BA8/H8) | BC8: =IF(OR(H8="",AY8=""),"",H8-AY8) | BD8: =IF(OR(BC8="",H8=""),"",BC8/H8) | BE8: 义乌 | BF8: ABE8 | BG8: 海运 | BH8: （最低价） | BI8: =IF(OR(BE8="",BF8=""),"",IF(AND(BH8<>"",BH8<>"（最低价）"),IFERROR(IF(SUMIFS(海运报价!$F$2:$F$2000,海运报价!$C$2:$C$2000,BH8,海运报价!$D$2:$D$2000,BE8,海运报价!$E$2:$E$2000,BF8)=0,"",SUMIFS(海运报价!$F$2:$F$2000,海运报价!$C$2:$C$2000,BH8,海运报价!$D$2:$D$2000,BE8,海运报价!$E$2:$E$2000,BF8)),""),IFERROR(IF(SUMIFS(海运下拉!$H$2:$H$311,海运下拉!$F$2:$F$311,BE8,海运下拉!$G$2:$G$311,BF8)=0,"",SUMIFS(海运下拉!$H$2:$H$311,海运下拉!$F$2:$F$311,BE8,海运下拉!$G$2:$G$311,BF8)),""))) | BJ8: =IF(C8="","",VLOOKUP($C8,箱规!$A$2:$S$23,18,FALSE)) | BK8: =IF(OR(BI8="",BJ8=""),"",BJ8*(BI8+IF(AND(BH8<>"",BH8<>"（最低价）"),IFERROR(AVERAGEIFS(海运报价!$H$2:$H$2000,海运报价!$C$2:$C$2000,BH8,海运报价!$D$2:$D$2000,BE8,海运报价!$E$2:$E$2000,BF8),0),IFERROR(SUMIFS(海运下拉!$J$2:$J$311,海运下拉!$F$2:$F$311,BE8,海运下拉!$G$2:$G$311,BF8),0)))) | BM8: =IF(OR(BE8="",BF8=""),"请选起运地+FBA仓",IF(AND(AND(BH8<>"",BH8<>"（最低价）"),BI8=""),"⚠该渠道不服务此仓：请重选渠道，或选「（最低价）」",IF(BI8="","无报价：请换起运地/仓库",IF(AND(BH8<>"",BH8<>"（最低价）"),"按你选的渠道「"&BH8&"」计价","按最低价「"&IFERROR(SUMIFS(海运下拉!$I$2:$I$311,海运下拉!$F$2:$F$311,BE8,海运下拉!$G$2:$G$311,BF8),"")&"」（渠道默认最低价）")))) | BO8: =IF(OR($BE8="",$BF8=""),"",IFERROR(INDEX(海运报价!$C$2:$C$2000,AGGREGATE(15,6,(ROW(海运报价!$C$2:$C$2000)-ROW(海运报价!$C$2)+1)/((海运报价!$D$2:$D$2000=$BE8)*(海运报价!$E$2:$E$2000=$BF8)),1)),"")) | BP8: =IF(OR($BE8="",$BF8=""),"",IFERROR(INDEX(海运报价!$C$2:$C$2000,AGGREGATE(15,6,(ROW(海运报价!$C$2:$C$2000)-ROW(海运报价!$C$2)+1)/((海运报价!$D$2:$D$2000=$BE8)*(海运报价!$E$2:$E$2000=$BF8)),2)),"")) | BQ8: =IF(OR($BE8="",$BF8=""),"",IFERROR(INDEX(海运报价!$C$2:$C$2000,AGGREGATE(15,6,(ROW(海运报价!$C$2:$C$2000)-ROW(海运报价!$C$2)+1)/((海运报价!$D$2:$D$2000=$BE8)*(海运报价!$E$2:$E$2000=$BF8)),3)),"")) | BR8: =IF(OR($BE8="",$BF8=""),"",IFERROR(INDEX(海运报价!$C$2:$C$2000,AGGREGATE(15,6,(ROW(海运报价!$C$2:$C$2000)-ROW(海运报价!$C$2)+1)/((海运报价!$D$2:$D$2000=$BE8)*(海运报价!$E$2:$E$2000=$BF8)),4)),"")) | BS8: =IF(OR($BE8="",$BF8=""),"",IFERROR(INDEX(海运报价!$C$2:$C$2000,AGGREGATE(15,6,(ROW(海运报价!$C$2:$C$2000)-ROW(海运报价!$C$2)+1)/((海运报价!$D$2:$D$2000=$BE8)*(海运报价!$E$2:$E$2000=$BF8)),5)),"")) | BT8: =IF(OR($BE8="",$BF8=""),"",IFERROR(INDEX(海运报价!$C$2:$C$2000,AGGREGATE(15,6,(ROW(海运报价!$C$2:$C$2000)-ROW(海运报价!$C$2)+1)/((海运报价!$D$2:$D$2000=$BE8)*(海运报价!$E$2:$E$2000=$BF8)),6)),"")) | BU8: =IF(OR($BE8="",$BF8=""),"",IFERROR(INDEX(海运报价!$C$2:$C$2000,AGGREGATE(15,6,(ROW(海运报价!$C$2:$C$2000)-ROW(海运报价!$C$2)+1)/((海运报价!$D$2:$D$2000=$BE8)*(海运报价!$E$2:$E$2000=$BF8)),7)),"")) | BV8: =IF(OR($BE8="",$BF8=""),"",IFERROR(INDEX(海运报价!$C$2:$C$2000,AGGREGATE(15,6,(ROW(海运报价!$C$2:$C$2000)-ROW(海运报价!$C$2)+1)/((海运报价!$D$2:$D$2000=$BE8)*(海运报价!$E$2:$E$2000=$BF8)),8)),"")) | BW8: =IF(OR($BE8="",$BF8=""),"",IFERROR(INDEX(海运报价!$C$2:$C$2000,AGGREGATE(15,6,(ROW(海运报价!$C$2:$C$2000)-ROW(海运报价!$C$2)+1)/((海运报价!$D$2:$D$2000=$BE8)*(海运报价!$E$2:$E$2000=$BF8)),9)),"")) | BX8: =IF(OR($BE8="",$BF8=""),"",IFERROR(INDEX(海运报价!$C$2:$C$2000,AGGREGATE(15,6,(ROW(海运报价!$C$2:$C$2000)-ROW(海运报价!$C$2)+1)/((海运报价!$D$2:$D$2000=$BE8)*(海运报价!$E$2:$E$2000=$BF8)),10)),"")) | BY8: =IF(OR($BE8="",$BF8=""),"",IFERROR(INDEX(海运报价!$C$2:$C$2000,AGGREGATE(15,6,(ROW(海运报价!$C$2:$C$2000)-ROW(海运报价!$C$2)+1)/((海运报价!$D$2:$D$2000=$BE8)*(海运报价!$E$2:$E$2000=$BF8)),11)),"")) | BZ8: =IF(OR($BE8="",$BF8=""),"",IFERROR(INDEX(海运报价!$C$2:$C$2000,AGGREGATE(15,6,(ROW(海运报价!$C$2:$C$2000)-ROW(海运报价!$C$2)+1)/((海运报价!$D$2:$D$2000=$BE8)*(海运报价!$E$2:$E$2000=$BF8)),12)),"")) | CA8: =IF(OR($BE8="",$BF8=""),"",IFERROR(INDEX(海运报价!$C$2:$C$2000,AGGREGATE(15,6,(ROW(海运报价!$C$2:$C$2000)-ROW(海运报价!$C$2)+1)/((海运报价!$D$2:$D$2000=$BE8)*(海运报价!$E$2:$E$2000=$BF8)),13)),"")) | CB8: =IF(OR($BE8="",$BF8=""),"",IFERROR(INDEX(海运报价!$C$2:$C$2000,AGGREGATE(15,6,(ROW(海运报价!$C$2:$C$2000)-ROW(海运报价!$C$2)+1)/((海运报价!$D$2:$D$2000=$BE8)*(海运报价!$E$2:$E$2000=$BF8)),14)),"")) | CC8: =IF(OR($BE8="",$BF8=""),"",IFERROR(INDEX(海运报价!$C$2:$C$2000,AGGREGATE(15,6,(ROW(海运报价!$C$2:$C$2000)-ROW(海运报价!$C$2)+1)/((海运报价!$D$2:$D$2000=$BE8)*(海运报价!$E$2:$E$2000=$BF8)),15)),"")) | CD8: =IF(OR(X8="",M8=""),"",X8+IF(OR(AA8="",M8=""),0,AA8/M8)+IF(AB8="",0,AB8)+IF(AI8="",0,AI8)+IF(Z8="",0,Z8)) | CE8: =I8+J8+K8+L8+AG8
C9: 3'5' | D9: =IF(C9="","",VLOOKUP($C9,箱规!$A$2:$S$23,9,FALSE)) | G9: =IF(OR(CD9="",CE9="",CE9>=1,X9=""),"",ROUNDUP((CD9-0.13*X9/1.13)/(1-CE9),2)) | H9: =IF(OR(CD9="",CE9="",X9=""),"",IF((1-CE9-参数!$B$16)<=0,"费率过高",ROUND((CD9-0.13*X9/1.13)/(1-CE9-参数!$B$16),2))) | I9: 0.15 | J9: 0.07 | K9: 0.15 | L9: 0.01 | M9: =参数!$B$2 | N9: =IF(C9="","",VLOOKUP($C9,箱规!$A$2:$S$23,14,FALSE)) | O9: =IF(C9="","",VLOOKUP($C9,箱规!$A$2:$S$23,5,FALSE)) | P9: =IF(C9="","",VLOOKUP($C9,箱规!$A$2:$S$23,6,FALSE)) | Q9: =IF(C9="","",VLOOKUP($C9,箱规!$A$2:$S$23,7,FALSE)) | R9: =IF(OR(N9="",O9="",P9="",Q9=""),"",MAX(N9*FBA规则!$B$6,(O9/FBA规则!$B$5)*(P9/FBA规则!$B$5)*(Q9/FBA规则!$B$5)/FBA规则!$B$7)) | S9: =IF(R9="","",IF(AND(N9*FBA规则!$B$6<=1,MAX(O9,P9,Q9)/FBA规则!$B$5<=15,MEDIAN(O9,P9,Q9)/FBA规则!$B$5<=12,MIN(O9,P9,Q9)/FBA规则!$B$5<=0.75),"小标准",IF(AND(R9<=20,MAX(O9,P9,Q9)/FBA规则!$B$5<=18,MEDIAN(O9,P9,Q9)/FBA规则!$B$5<=14,MIN(O9,P9,Q9)/FBA规则!$B$5<=8),"大标准",IF(AND(R9<=50,MAX(O9,P9,Q9)/FBA规则!$B$5<=59,MEDIAN(O9,P9,Q9)/FBA规则!$B$5<=33,MIN(O9,P9,Q9)/FBA规则!$B$5<=33,T9<=130),"大件",IF(R9<=50,"超大0-50lb",IF(R9<=70,"超大50-70lb",IF(R9<=150,"超大70-150lb","超大150lb+"))))))) | T9: =IF(OR(O9="",P9="",Q9=""),"",MAX(O9,P9,Q9)/FBA规则!$B$5+2*((MEDIAN(O9,P9,Q9)+MIN(O9,P9,Q9))/FBA规则!$B$5)) | U9: =参数!$B$15 | V9: =IF(OR(C9="",U9=""),"",(IF(OR(VLOOKUP($C9,箱规!$A$2:$S$23,4,FALSE)="",VLOOKUP($C9,箱规!$A$2:$S$23,4,FALSE)=0),VLOOKUP($C9,箱规!$A$2:$S$23,2,FALSE)*VLOOKUP($C9,箱规!$A$2:$S$23,3,FALSE)/10000,VLOOKUP($C9,箱规!$A$2:$S$23,4,FALSE)))*U9) | X9: =IF(AND(V9<>"",M9<>""),V9/M9,IF(AND(W9<>"",M9<>""),W9*1.13/M9,"")) | Y9: =IF(OR(X9="",G9=""),"",X9/G9) | AA9: =IF(OR(D9="",D9=0),"",IF(BG9="陆运",IF(BL9="",0,BL9)/D9,IF(BG9="海运",IF(BK9="",0,BK9)/D9,IF(BG9="海运+陆运",(IF(BK9="",0,BK9)+IF(BL9="",0,BL9))/D9,IF(BK9="",0,BK9)/D9)))) | AB9: =IF(OR(S9="",R9="",参数!$B$23=""),"",IF(S9="小标准",IFERROR(INDEX(FBA规则!$B$58:$C$65,MATCH(N9*FBA规则!$B$6*16,FBA规则!$A$58:$A$65,1),IF(参数!$B$23="旺季",2,1)),INDEX(FBA规则!$B$65:$C$65,1,IF(参数!$B$23="旺季",2,1))),IF(S9="大标准",IF(R9<=3,IFERROR(INDEX(FBA规则!$B$35:$C$46,MATCH(R9,FBA规则!$A$35:$A$46,1),IF(参数!$B$23="旺季",2,1)),INDEX(FBA规则!$B$46:$C$46,1,IF(参数!$B$23="旺季",2,1))),INDEX(FBA规则!$B$47:$C$47,1,IF(参数!$B$23="旺季",2,1))+FBA规则!$D$47*CEILING((R9-3)*4,1)),IF(S9="大件",INDEX(FBA规则!$B$50:$C$50,1,IF(参数!$B$23="旺季",2,1))+FBA规则!$D$50*MAX(0,CEILING(R9,1)-1),IF(S9="超大0-50lb",INDEX(FBA规则!$B$51:$C$51,1,IF(参数!$B$23="旺季",2,1))+FBA规则!$D$51*MAX(0,CEILING(R9,1)-1),IF(S9="超大50-70lb",INDEX(FBA规则!$B$52:$C$52,1,IF(参数!$B$23="旺季",2,1))+FBA规则!$D$52*MAX(0,R9-FBA规则!$F$52),IF(S9="超大70-150lb",INDEX(FBA规则!$B$53:$C$53,1,IF(参数!$B$23="旺季",2,1))+FBA规则!$D$53*MAX(0,R9-FBA规则!$F$53),INDEX(FBA规则!$B$54:$C$54,1,IF(参数!$B$23="旺季",2,1))+FBA规则!$D$54*MAX(0,R9-FBA规则!$F$54)))))))) | AC9: =IF(OR(G9="",I9=""),"",G9*I9) | AD9: =IF(OR(G9="",J9=""),"",G9*J9) | AE9: =IF(OR(G9="",K9=""),"",G9*K9) | AF9: =IF(OR(G9="",L9=""),"",G9*L9) | AG9: 0.02 | AH9: =IF(OR(G9="",AG9=""),"",G9*AG9) | AJ9: =IF(X9="","",X9+IF(OR(AA9="",M9=""),0,AA9/M9)+SUM(AB9:AF9)+IF(AH9="",0,AH9)+IF(AI9="",0,AI9)) | AK9: =IF(X9="","",0.13*X9/1.13) | AL9: =IF(OR(G9="",AJ9=""),"",G9+AK9-AJ9) | AM9: =IF(OR(AL9="",G9=""),"",AL9/G9) | AN9: =IF(OR(X9="",H9=""),"",X9/H9) | AP9: =AA9 | AQ9: =IF(OR(S9="",R9="",参数!$B$23=""),"",IF(S9="小标准",IFERROR(INDEX(FBA规则!$B$58:$C$65,MATCH(N9*FBA规则!$B$6*16,FBA规则!$A$58:$A$65,1),IF(参数!$B$23="旺季",2,1)),INDEX(FBA规则!$B$65:$C$65,1,IF(参数!$B$23="旺季",2,1))),IF(S9="大标准",IF(R9<=3,IFERROR(INDEX(FBA规则!$B$35:$C$46,MATCH(R9,FBA规则!$A$35:$A$46,1),IF(参数!$B$23="旺季",2,1)),INDEX(FBA规则!$B$46:$C$46,1,IF(参数!$B$23="旺季",2,1))),INDEX(FBA规则!$B$47:$C$47,1,IF(参数!$B$23="旺季",2,1))+FBA规则!$D$47*CEILING((R9-3)*4,1)),IF(S9="大件",INDEX(FBA规则!$B$50:$C$50,1,IF(参数!$B$23="旺季",2,1))+FBA规则!$D$50*MAX(0,CEILING(R9,1)-1),IF(S9="超大0-50lb",INDEX(FBA规则!$B$51:$C$51,1,IF(参数!$B$23="旺季",2,1))+FBA规则!$D$51*MAX(0,CEILING(R9,1)-1),IF(S9="超大50-70lb",INDEX(FBA规则!$B$52:$C$52,1,IF(参数!$B$23="旺季",2,1))+FBA规则!$D$52*MAX(0,R9-FBA规则!$F$52),IF(S9="超大70-150lb",INDEX(FBA规则!$B$53:$C$53,1,IF(参数!$B$23="旺季",2,1))+FBA规则!$D$53*MAX(0,R9-FBA规则!$F$53),INDEX(FBA规则!$B$54:$C$54,1,IF(参数!$B$23="旺季",2,1))+FBA规则!$D$54*MAX(0,R9-FBA规则!$F$54)))))))) | AR9: =IF(OR(H9="",I9=""),"",H9*I9) | AS9: =IF(OR(H9="",J9=""),"",H9*J9) | AT9: =IF(OR(H9="",K9=""),"",H9*K9) | AU9: =IF(OR(H9="",L9=""),"",H9*L9) | AV9: 0.02 | AW9: =IF(OR(H9="",AV9=""),"",H9*AV9) | AY9: =IF(X9="","",X9+IF(OR(AP9="",M9=""),0,AP9/M9)+SUM(AQ9:AU9)+IF(AW9="",0,AW9)+IF(AX9="",0,AX9)) | AZ9: =IF(X9="","",0.13*X9/1.13) | BA9: =IF(OR(H9="",AY9=""),"",H9+AZ9-AY9) | BB9: =IF(OR(BA9="",H9=""),"",BA9/H9) | BC9: =IF(OR(H9="",AY9=""),"",H9-AY9) | BD9: =IF(OR(BC9="",H9=""),"",BC9/H9) | BE9: 义乌 | BF9: ABE8 | BG9: 海运 | BH9: （最低价） | BI9: =IF(OR(BE9="",BF9=""),"",IF(AND(BH9<>"",BH9<>"（最低价）"),IFERROR(IF(SUMIFS(海运报价!$F$2:$F$2000,海运报价!$C$2:$C$2000,BH9,海运报价!$D$2:$D$2000,BE9,海运报价!$E$2:$E$2000,BF9)=0,"",SUMIFS(海运报价!$F$2:$F$2000,海运报价!$C$2:$C$2000,BH9,海运报价!$D$2:$D$2000,BE9,海运报价!$E$2:$E$2000,BF9)),""),IFERROR(IF(SUMIFS(海运下拉!$H$2:$H$311,海运下拉!$F$2:$F$311,BE9,海运下拉!$G$2:$G$311,BF9)=0,"",SUMIFS(海运下拉!$H$2:$H$311,海运下拉!$F$2:$F$311,BE9,海运下拉!$G$2:$G$311,BF9)),""))) | BJ9: =IF(C9="","",VLOOKUP($C9,箱规!$A$2:$S$23,18,FALSE)) | BK9: =IF(OR(BI9="",BJ9=""),"",BJ9*(BI9+IF(AND(BH9<>"",BH9<>"（最低价）"),IFERROR(AVERAGEIFS(海运报价!$H$2:$H$2000,海运报价!$C$2:$C$2000,BH9,海运报价!$D$2:$D$2000,BE9,海运报价!$E$2:$E$2000,BF9),0),IFERROR(SUMIFS(海运下拉!$J$2:$J$311,海运下拉!$F$2:$F$311,BE9,海运下拉!$G$2:$G$311,BF9),0)))) | BM9: =IF(OR(BE9="",BF9=""),"请选起运地+FBA仓",IF(AND(AND(BH9<>"",BH9<>"（最低价）"),BI9=""),"⚠该渠道不服务此仓：请重选渠道，或选「（最低价）」",IF(BI9="","无报价：请换起运地/仓库",IF(AND(BH9<>"",BH9<>"（最低价）"),"按你选的渠道「"&BH9&"」计价","按最低价「"&IFERROR(SUMIFS(海运下拉!$I$2:$I$311,海运下拉!$F$2:$F$311,BE9,海运下拉!$G$2:$G$311,BF9),"")&"」（渠道默认最低价）")))) | BO9: =IF(OR($BE9="",$BF9=""),"",IFERROR(INDEX(海运报价!$C$2:$C$2000,AGGREGATE(15,6,(ROW(海运报价!$C$2:$C$2000)-ROW(海运报价!$C$2)+1)/((海运报价!$D$2:$D$2000=$BE9)*(海运报价!$E$2:$E$2000=$BF9)),1)),"")) | BP9: =IF(OR($BE9="",$BF9=""),"",IFERROR(INDEX(海运报价!$C$2:$C$2000,AGGREGATE(15,6,(ROW(海运报价!$C$2:$C$2000)-ROW(海运报价!$C$2)+1)/((海运报价!$D$2:$D$2000=$BE9)*(海运报价!$E$2:$E$2000=$BF9)),2)),"")) | BQ9: =IF(OR($BE9="",$BF9=""),"",IFERROR(INDEX(海运报价!$C$2:$C$2000,AGGREGATE(15,6,(ROW(海运报价!$C$2:$C$2000)-ROW(海运报价!$C$2)+1)/((海运报价!$D$2:$D$2000=$BE9)*(海运报价!$E$2:$E$2000=$BF9)),3)),"")) | BR9: =IF(OR($BE9="",$BF9=""),"",IFERROR(INDEX(海运报价!$C$2:$C$2000,AGGREGATE(15,6,(ROW(海运报价!$C$2:$C$2000)-ROW(海运报价!$C$2)+1)/((海运报价!$D$2:$D$2000=$BE9)*(海运报价!$E$2:$E$2000=$BF9)),4)),"")) | BS9: =IF(OR($BE9="",$BF9=""),"",IFERROR(INDEX(海运报价!$C$2:$C$2000,AGGREGATE(15,6,(ROW(海运报价!$C$2:$C$2000)-ROW(海运报价!$C$2)+1)/((海运报价!$D$2:$D$2000=$BE9)*(海运报价!$E$2:$E$2000=$BF9)),5)),"")) | BT9: =IF(OR($BE9="",$BF9=""),"",IFERROR(INDEX(海运报价!$C$2:$C$2000,AGGREGATE(15,6,(ROW(海运报价!$C$2:$C$2000)-ROW(海运报价!$C$2)+1)/((海运报价!$D$2:$D$2000=$BE9)*(海运报价!$E$2:$E$2000=$BF9)),6)),"")) | BU9: =IF(OR($BE9="",$BF9=""),"",IFERROR(INDEX(海运报价!$C$2:$C$2000,AGGREGATE(15,6,(ROW(海运报价!$C$2:$C$2000)-ROW(海运报价!$C$2)+1)/((海运报价!$D$2:$D$2000=$BE9)*(海运报价!$E$2:$E$2000=$BF9)),7)),"")) | BV9: =IF(OR($BE9="",$BF9=""),"",IFERROR(INDEX(海运报价!$C$2:$C$2000,AGGREGATE(15,6,(ROW(海运报价!$C$2:$C$2000)-ROW(海运报价!$C$2)+1)/((海运报价!$D$2:$D$2000=$BE9)*(海运报价!$E$2:$E$2000=$BF9)),8)),"")) | BW9: =IF(OR($BE9="",$BF9=""),"",IFERROR(INDEX(海运报价!$C$2:$C$2000,AGGREGATE(15,6,(ROW(海运报价!$C$2:$C$2000)-ROW(海运报价!$C$2)+1)/((海运报价!$D$2:$D$2000=$BE9)*(海运报价!$E$2:$E$2000=$BF9)),9)),"")) | BX9: =IF(OR($BE9="",$BF9=""),"",IFERROR(INDEX(海运报价!$C$2:$C$2000,AGGREGATE(15,6,(ROW(海运报价!$C$2:$C$2000)-ROW(海运报价!$C$2)+1)/((海运报价!$D$2:$D$2000=$BE9)*(海运报价!$E$2:$E$2000=$BF9)),10)),"")) | BY9: =IF(OR($BE9="",$BF9=""),"",IFERROR(INDEX(海运报价!$C$2:$C$2000,AGGREGATE(15,6,(ROW(海运报价!$C$2:$C$2000)-ROW(海运报价!$C$2)+1)/((海运报价!$D$2:$D$2000=$BE9)*(海运报价!$E$2:$E$2000=$BF9)),11)),"")) | BZ9: =IF(OR($BE9="",$BF9=""),"",IFERROR(INDEX(海运报价!$C$2:$C$2000,AGGREGATE(15,6,(ROW(海运报价!$C$2:$C$2000)-ROW(海运报价!$C$2)+1)/((海运报价!$D$2:$D$2000=$BE9)*(海运报价!$E$2:$E$2000=$BF9)),12)),"")) | CA9: =IF(OR($BE9="",$BF9=""),"",IFERROR(INDEX(海运报价!$C$2:$C$2000,AGGREGATE(15,6,(ROW(海运报价!$C$2:$C$2000)-ROW(海运报价!$C$2)+1)/((海运报价!$D$2:$D$2000=$BE9)*(海运报价!$E$2:$E$2000=$BF9)),13)),"")) | CB9: =IF(OR($BE9="",$BF9=""),"",IFERROR(INDEX(海运报价!$C$2:$C$2000,AGGREGATE(15,6,(ROW(海运报价!$C$2:$C$2000)-ROW(海运报价!$C$2)+1)/((海运报价!$D$2:$D$2000=$BE9)*(海运报价!$E$2:$E$2000=$BF9)),14)),"")) | CC9: =IF(OR($BE9="",$BF9=""),"",IFERROR(INDEX(海运报价!$C$2:$C$2000,AGGREGATE(15,6,(ROW(海运报价!$C$2:$C$2000)-ROW(海运报价!$C$2)+1)/((海运报价!$D$2:$D$2000=$BE9)*(海运报价!$E$2:$E$2000=$BF9)),15)),"")) | CD9: =IF(OR(X9="",M9=""),"",X9+IF(OR(AA9="",M9=""),0,AA9/M9)+IF(AB9="",0,AB9)+IF(AI9="",0,AI9)+IF(Z9="",0,Z9)) | CE9: =I9+J9+K9+L9+AG9
